Workbook

Sheet Cover & Instructions
B2: CHAK Monthly Project Performance Monitoring Template
B4: Financial performance (burn rate & Budget vs. Actual) combined with technical/donor indicator performance — across all 10 CHAK project portfolios: Jamii Tekelezi, CHAP Stawisha, Eye Health - ACSP & GitLab, EIS, BFTW HSS, BFTW RMNCAH, PEP, GF-MNCH, IMPACT and CDIC-iCARE.
B6: HOW TO USE THIS WORKBOOK
B7: 1. Each of the 10 project tabs has the same structure: project header (donor, project code, reporting month/period, duration, months elapsed), Section A — Financial Performance (9 budget lines + a Total Project Budget row), Section B — Technical/Donor Indicator Performance (8 indicators), and Section C — Overall Project Health (Financial RAG, Technical RAG, and a combined Overall RAG).
B9: 2. Enter blue-font cells only — these are inputs (annual budget per line, project duration, months elapsed, actual cumulative expenditure, current-month spend, annual target per indicator, actual cumulative result). Black-font cells are formulas — do not overtype them. Green-font cells link from another tab (Portfolio Dashboard only).
B11: 3. "Months Elapsed" and "Project Duration (months)" drive the linear planned (expected) cumulative budget and target for every budget line and indicator — adjust the planned-progress formula if a project's spend or target profile is not even/straight-line across the year.
B13: 4. RAG status is automatic. Financial: variance within ±10% of planned cumulative spend = On Track, ±10-20% = Watch, beyond ±20% = Off Track (both over- and under-spend are flagged, since underspend signals an absorption/refund risk). Technical: achievement ≥90% of planned cumulative target = On Track, 75-89% = Watch, below 75% = Off Track. Section C combines both: Financial RAG (from the Total Project Budget row), Technical RAG (the worst rating among the 8 indicators), and Overall Project Health (the worst of the two).
B15: 5. The Portfolio Dashboard tab pulls live figures from all 10 project tabs — including each project's Financial RAG, Technical RAG, indicators-off-track count and Overall RAG — and rolls them up into a CEO Snapshot (counts of On Track / Watch / Off Track projects and overall budget utilisation). Refresh it after updating any project tab; no manual entry is needed there.
B17: 6. Update this workbook once a month, after the reporting month closes, using actual cumulative expenditure and indicator results from finance and M&E records for each project.
B19: 7. Indicator names, donor names and project codes shown are illustrative placeholders — replace them with each project's specific donor M&E framework indicators, definitions, reporting frequency, and contractual donor/code details where they differ.
B22: COLOR KEY
B23: Blue text | C23: Input cell — edit this
B24: Black text | C24: Formula — do not edit
B25: Green text | C25: Link pulling from another tab
B27: On Track
B28: Watch
B29: Off Track

Sheet Portfolio Dashboard
B2: CHAK Project Portfolio — Monthly Health Dashboard
B3: Auto-populated from each project tab — refresh after updating any project's monthly data.
B5: Project | C5: Donor | D5: Total Annual Budget | E5: Cumulative Expenditure | F5: Budget Variance (%) | G5: Financial RAG | H5: Technical RAG | I5: Indicators Off Track | J5: Overall RAG
B6: Jamii Tekelezi | C6: ='Jamii Tekelezi'!C4 -> US - DOS | D6: ='Jamii Tekelezi'!C18 -> 68500000 | E6: ='Jamii Tekelezi'!E18 -> 36755000 | F6: ='Jamii Tekelezi'!G18 -> 0.073138686 | G6: ='Jamii Tekelezi'!E34 -> Watch | H6: ='Jamii Tekelezi'!E35 -> Off Track | I6: ='Jamii Tekelezi'!J35 -> 1 of 8 | J6: ='Jamii Tekelezi'!E36 -> Off Track
B7: CHAP Stawisha | C7: ='CHAP Stawisha'!C4 -> CDC | D7: ='CHAP Stawisha'!C18 -> 0 | E7: ='CHAP Stawisha'!E18 -> 0 | F7: ='CHAP Stawisha'!G18 -> N/A | G7: ='CHAP Stawisha'!E34 -> N/A | H7: ='CHAP Stawisha'!E35 -> Off Track | I7: ='CHAP Stawisha'!J35 -> 1 of 8 | J7: ='CHAP Stawisha'!E36 -> Off Track
B8: Eye Health - ACSP & GitLab | C8: ='Eye Health - ACSP & GitLab'!C4 -> ACHAP / GitLab Foundation | D8: ='Eye Health - ACSP & GitLab'!C18 -> 68500000 | E8: ='Eye Health - ACSP & GitLab'!E18 -> 25687500 | F8: ='Eye Health - ACSP & GitLab'!G18 -> -0.1 | G8: ='Eye Health - ACSP & GitLab'!E34 -> On Track | H8: ='Eye Health - ACSP & GitLab'!E35 -> On Track | I8: ='Eye Health - ACSP & GitLab'!J35 -> 0 of 8 | J8: ='Eye Health - ACSP & GitLab'!E36 -> On Track
B9: EIS | C9: =EIS!C4 -> Bill & Melinda Gates Foundation | D9: =EIS!C18 -> 68500000 | E9: =EIS!E18 -> 35677084 | F9: =EIS!G18 -> 0.25000002 | G9: =EIS!E34 -> Off Track | H9: =EIS!E35 -> Off Track | I9: =EIS!J35 -> 8 of 8 | J9: =EIS!E36 -> Off Track
B10: BFTW HSS | C10: ='BFTW HSS'!C4 -> Bread for the World | D10: ='BFTW HSS'!C18 -> 68500000 | E10: ='BFTW HSS'!E18 -> 27685416 | F10: ='BFTW HSS'!G18 -> -0.030000023 | G10: ='BFTW HSS'!E34 -> On Track | H10: ='BFTW HSS'!E35 -> Watch | I10: ='BFTW HSS'!J35 -> 0 of 8 | J10: ='BFTW HSS'!E36 -> Watch
B11: BFTW RMNCAH | C11: ='BFTW RMNCAH'!C4 -> Bread for the World | D11: ='BFTW RMNCAH'!C18 -> 68500000 | E11: ='BFTW RMNCAH'!E18 -> 29968750 | F11: ='BFTW RMNCAH'!G18 -> 0.05 | G11: ='BFTW RMNCAH'!E34 -> On Track | H11: ='BFTW RMNCAH'!E35 -> On Track | I11: ='BFTW RMNCAH'!J35 -> 0 of 8 | J11: ='BFTW RMNCAH'!E36 -> On Track
B12: PEP | C12: =PEP!C4 -> Novo Nordisk Foundation (NNF) | D12: =PEP!C18 -> 68500000 | E12: =PEP!E18 -> 11873334 | F12: =PEP!G18 -> -0.21999996 | G12: =PEP!E34 -> Off Track | H12: =PEP!E35 -> On Track | I12: =PEP!J35 -> 0 of 8 | J12: =PEP!E36 -> Off Track
B13: GF-MNCH | C13: ='GF-MNCH'!C4 -> Bill & Melinda Gates Foundation | D13: ='GF-MNCH'!C18 -> 68500000 | E13: ='GF-MNCH'!E18 -> 34592500 | F13: ='GF-MNCH'!G18 -> 0.01 | G13: ='GF-MNCH'!E34 -> On Track | H13: ='GF-MNCH'!E35 -> On Track | I13: ='GF-MNCH'!J35 -> 0 of 8 | J13: ='GF-MNCH'!E36 -> On Track
B14: IMPACT | C14: =IMPACT!C4 -> action medeor | D14: =IMPACT!C18 -> 68500000 | E14: =IMPACT!E18 -> 51945834 | F14: =IMPACT!G18 -> 0.30000002 | G14: =IMPACT!E34 -> Off Track | H14: =IMPACT!E35 -> Off Track | I14: =IMPACT!J35 -> 8 of 8 | J14: =IMPACT!E36 -> Off Track
B15: CDIC-iCARE | C15: ='CDIC-iCARE'!C4 -> CDC / iCARE | D15: ='CDIC-iCARE'!C18 -> 68500000 | E15: ='CDIC-iCARE'!E18 -> 24660000 | F15: ='CDIC-iCARE'!G18 -> 0.08 | G15: ='CDIC-iCARE'!E34 -> On Track | H15: ='CDIC-iCARE'!E35 -> Watch | I15: ='CDIC-iCARE'!J35 -> 0 of 8 | J15: ='CDIC-iCARE'!E36 -> Watch
B16: PORTFOLIO TOTAL | D16: =SUM(D6:D15) -> 616500000 | E16: =SUM(E6:E15) -> 278845418 | F16: ="See project tabs for planned-vs-actual detail" -> See project tabs for planned-vs-actual detail
B18: CEO SNAPSHOT — PORTFOLIO STATUS AT A GLANCE
B19: Projects On Track (Overall RAG): | D19: =COUNTIF(J6:J15,"On Track")&" of "&COUNTA(J6:J15) -> 3 of 10 | E19: Projects on Watch: | G19: =COUNTIF(J6:J15,"Watch")&" of "&COUNTA(J6:J15) -> 2 of 10
B20: Projects Off Track (Overall RAG): | D20: =COUNTIF(J6:J15,"Off Track")&" of "&COUNTA(J6:J15) -> 5 of 10 | E20: Portfolio Budget Utilisation: | G20: =IF(D16=0,"N/A",E16/D16) -> 0.452304
B22: RAG LEGEND: On Track = within tolerance · Watch = approaching threshold, needs attention · Off Track = requires corrective action

Sheet Jamii Tekelezi
B2: Jamii Tekelezi Monthly Performance Monitoring
B4: Donor: | C4: US - DOS | E4: Reporting Month: | G4: =TODAY() -> 46202 | I4: Project Duration (months): | K4: 12
B5: Project Code: | C5: CHAK/2026/01 | E5: Reporting Period: | G5: Type reporting period here... | I5: Months Elapsed to Date: | K5: 6
B7: SECTION A · FINANCIAL PERFORMANCE — BURN RATE & BUDGET VS. ACTUAL (BVA)
B8: Budget Line | C8: Annual Budget | D8: Planned Cumulative Budget to Date | E8: Actual Cumulative Expenditure to Date | F8: Variance ($) | G8: Variance (%) | H8: Current Month Expenditure | I8: Avg. Monthly Burn Rate | J8: Projected Annual Expenditure | K8: Months Remaining | L8: RAG
B9: Personnel & HR | C9: 18000000 | D9: =C9*$K$5/$K$4 -> 9000000 | E9: 11000000 | F9: =E9-D9 -> 2000000 | G9: =IF(D9=0,"N/A",F9/D9) -> 0.22222222 | H9: 1530000 | I9: =IF($K$5=0,"N/A",E9/$K$5) -> 1833333.3 | J9: =IF(C9=0,"N/A",I9*$K$4) -> 22000000 | K9: =IF($K$4-$K$5<0,0,$K$4-$K$5) -> 6 | L9: =IF(G9="N/A","N/A",IF(ABS(G9)<=0.05,"On Track",IF(ABS(G9)<=0.1,"Watch","Off Track"))) -> Off Track
B10: Technical / Program Activities | C10: 9000000 | D10: =C10*$K$5/$K$4 -> 4500000 | E10: 4590000 | F10: =E10-D10 -> 90000 | G10: =IF(D10=0,"N/A",F10/D10) -> 0.02 | H10: 765000 | I10: =IF($K$5=0,"N/A",E10/$K$5) -> 765000 | J10: =IF(C10=0,"N/A",I10*$K$4) -> 9180000 | K10: =IF($K$4-$K$5<0,0,$K$4-$K$5) -> 6 | L10: =IF(G10="N/A","N/A",IF(ABS(G10)<=0.05,"On Track",IF(ABS(G10)<=0.1,"Watch","Off Track"))) -> On Track
B11: Equipment, Supplies & Commodities | C11: 7500000 | D11: =C11*$K$5/$K$4 -> 3750000 | E11: 3825000 | F11: =E11-D11 -> 75000 | G11: =IF(D11=0,"N/A",F11/D11) -> 0.02 | H11: 637500 | I11: =IF($K$5=0,"N/A",E11/$K$5) -> 637500 | J11: =IF(C11=0,"N/A",I11*$K$4) -> 7650000 | K11: =IF($K$4-$K$5<0,0,$K$4-$K$5) -> 6 | L11: =IF(G11="N/A","N/A",IF(ABS(G11)<=0.05,"On Track",IF(ABS(G11)<=0.1,"Watch","Off Track"))) -> On Track
B12: Training & Capacity Building | C12: 6000000 | D12: =C12*$K$5/$K$4 -> 3000000 | E12: 3060000 | F12: =E12-D12 -> 60000 | G12: =IF(D12=0,"N/A",F12/D12) -> 0.02 | H12: 510000 | I12: =IF($K$5=0,"N/A",E12/$K$5) -> 510000 | J12: =IF(C12=0,"N/A",I12*$K$4) -> 6120000 | K12: =IF($K$4-$K$5<0,0,$K$4-$K$5) -> 6 | L12: =IF(G12="N/A","N/A",IF(ABS(G12)<=0.05,"On Track",IF(ABS(G12)<=0.1,"Watch","Off Track"))) -> On Track
B13: Sub-awards / Partner Disbursements | C13: 9500000 | D13: =C13*$K$5/$K$4 -> 4750000 | E13: 4845000 | F13: =E13-D13 -> 95000 | G13: =IF(D13=0,"N/A",F13/D13) -> 0.02 | H13: 807500 | I13: =IF($K$5=0,"N/A",E13/$K$5) -> 807500 | J13: =IF(C13=0,"N/A",I13*$K$4) -> 9690000 | K13: =IF($K$4-$K$5<0,0,$K$4-$K$5) -> 6 | L13: =IF(G13="N/A","N/A",IF(ABS(G13)<=0.05,"On Track",IF(ABS(G13)<=0.1,"Watch","Off Track"))) -> On Track
B14: Monitoring, Evaluation & Learning | C14: 4000000 | D14: =C14*$K$5/$K$4 -> 2000000 | E14: 2040000 | F14: =E14-D14 -> 40000 | G14: =IF(D14=0,"N/A",F14/D14) -> 0.02 | H14: 340000 | I14: =IF($K$5=0,"N/A",E14/$K$5) -> 340000 | J14: =IF(C14=0,"N/A",I14*$K$4) -> 4080000 | K14: =IF($K$4-$K$5<0,0,$K$4-$K$5) -> 6 | L14: =IF(G14="N/A","N/A",IF(ABS(G14)<=0.05,"On Track",IF(ABS(G14)<=0.1,"Watch","Off Track"))) -> On Track
B15: Travel & Transport | C15: 6500000 | D15: =C15*$K$5/$K$4 -> 3250000 | E15: 3315000 | F15: =E15-D15 -> 65000 | G15: =IF(D15=0,"N/A",F15/D15) -> 0.02 | H15: 552500 | I15: =IF($K$5=0,"N/A",E15/$K$5) -> 552500 | J15: =IF(C15=0,"N/A",I15*$K$4) -> 6630000 | K15: =IF($K$4-$K$5<0,0,$K$4-$K$5) -> 6 | L15: =IF(G15="N/A","N/A",IF(ABS(G15)<=0.05,"On Track",IF(ABS(G15)<=0.1,"Watch","Off Track"))) -> On Track
B16: Administration & Overheads | C16: 3000000 | D16: =C16*$K$5/$K$4 -> 1500000 | E16: 1530000 | F16: =E16-D16 -> 30000 | G16: =IF(D16=0,"N/A",F16/D16) -> 0.02 | H16: 255000 | I16: =IF($K$5=0,"N/A",E16/$K$5) -> 255000 | J16: =IF(C16=0,"N/A",I16*$K$4) -> 3060000 | K16: =IF($K$4-$K$5<0,0,$K$4-$K$5) -> 6 | L16: =IF(G16="N/A","N/A",IF(ABS(G16)<=0.05,"On Track",IF(ABS(G16)<=0.1,"Watch","Off Track"))) -> On Track
B17: Other Direct Costs / Contingency | C17: 5000000 | D17: =C17*$K$5/$K$4 -> 2500000 | E17: 2550000 | F17: =E17-D17 -> 50000 | G17: =IF(D17=0,"N/A",F17/D17) -> 0.02 | H17: 425000 | I17: =IF($K$5=0,"N/A",E17/$K$5) -> 425000 | J17: =IF(C17=0,"N/A",I17*$K$4) -> 5100000 | K17: =IF($K$4-$K$5<0,0,$K$4-$K$5) -> 6 | L17: =IF(G17="N/A","N/A",IF(ABS(G17)<=0.05,"On Track",IF(ABS(G17)<=0.1,"Watch","Off Track"))) -> On Track
B18: TOTAL PROJECT BUDGET | C18: =SUM(C9:C17) -> 68500000 | D18: =SUM(D9:D17) -> 34250000 | E18: =SUM(E9:E17) -> 36755000 | F18: =E18-D18 -> 2505000 | G18: =IF(D18=0,"N/A",F18/D18) -> 0.073138686 | H18: =SUM(H9:H17) -> 5822500 | I18: =IF($K$5=0,"N/A",E18/$K$5) -> 6125833.3 | J18: =IF(C18=0,"N/A",I18*$K$4) -> 73510000 | K18: =IF($K$4-$K$5<0,0,$K$4-$K$5) -> 6 | L18: =IF(G18="N/A","N/A",IF(ABS(G18)<=0.05,"On Track",IF(ABS(G18)<=0.1,"Watch","Off Track"))) -> Watch
B19: Planned cumulative budget assumes even (straight-line) spend across the project duration. Variance >20% in either direction triggers Off Track — overspend risks a funding gap; underspend risks an end-of-award absorption/refund issue.
B21: SECTION B · TECHNICAL / DONOR INDICATOR PERFORMANCE
B22: Indicator | C22: Unit / Definition | D22: Annual Target | E22: Planned Cumulative Target to Date | F22: Actual Cumulative Result to Date | G22: Achievement (%) | L22: RAG
B23: Tracer Indicator 1 | C23: Define per donor M&E framework | D23: 1200 | E23: =D23*$K$5/$K$4 -> 600 | F23: 400 | G23: =IF(E23=0,"N/A",F23/E23) -> 0.66666667 | L23: =IF(G23="N/A","N/A",IF(G23>=0.9,"On Track",IF(G23>=0.75,"Watch","Off Track"))) -> Off Track
B24: Tracer Indicator 2 | C24: Define per donor M&E framework | D24: 600 | E24: =D24*$K$5/$K$4 -> 300 | F24: 250 | G24: =IF(E24=0,"N/A",F24/E24) -> 0.83333333 | L24: =IF(G24="N/A","N/A",IF(G24>=0.9,"On Track",IF(G24>=0.75,"Watch","Off Track"))) -> Watch
B25: Tracer Indicator 3 | C25: Define per donor M&E framework | D25: 900 | E25: =D25*$K$5/$K$4 -> 450 | F25: 428 | G25: =IF(E25=0,"N/A",F25/E25) -> 0.95111111 | L25: =IF(G25="N/A","N/A",IF(G25>=0.9,"On Track",IF(G25>=0.75,"Watch","Off Track"))) -> On Track
B26: Tracer Indicator 4 | C26: Define per donor M&E framework | D26: 450 | E26: =D26*$K$5/$K$4 -> 225 | F26: 214 | G26: =IF(E26=0,"N/A",F26/E26) -> 0.95111111 | L26: =IF(G26="N/A","N/A",IF(G26>=0.9,"On Track",IF(G26>=0.75,"Watch","Off Track"))) -> On Track
B27: Tracer Indicator 5 | C27: Define per donor M&E framework | D27: 1500 | E27: =D27*$K$5/$K$4 -> 750 | F27: 712 | G27: =IF(E27=0,"N/A",F27/E27) -> 0.94933333 | L27: =IF(G27="N/A","N/A",IF(G27>=0.9,"On Track",IF(G27>=0.75,"Watch","Off Track"))) -> On Track
B28: Tracer Indicator 6 | C28: Define per donor M&E framework | D28: 300 | E28: =D28*$K$5/$K$4 -> 150 | F28: 142 | G28: =IF(E28=0,"N/A",F28/E28) -> 0.94666667 | L28: =IF(G28="N/A","N/A",IF(G28>=0.9,"On Track",IF(G28>=0.75,"Watch","Off Track"))) -> On Track
B29: Tracer Indicator 7 | C29: Define per donor M&E framework | D29: 750 | E29: =D29*$K$5/$K$4 -> 375 | F29: 356 | G29: =IF(E29=0,"N/A",F29/E29) -> 0.94933333 | L29: =IF(G29="N/A","N/A",IF(G29>=0.9,"On Track",IF(G29>=0.75,"Watch","Off Track"))) -> On Track
B30: Tracer Indicator 8 | C30: Define per donor M&E framework | D30: 200 | E30: =D30*$K$5/$K$4 -> 100 | F30: 95 | G30: =IF(E30=0,"N/A",F30/E30) -> 0.95 | L30: =IF(G30="N/A","N/A",IF(G30>=0.9,"On Track",IF(G30>=0.75,"Watch","Off Track"))) -> On Track
B31: Indicator names are standard/illustrative donor indicators for this project type — replace with your specific donor's exact indicator list, definitions and reporting frequency where they differ.
B33: SECTION C · OVERALL PROJECT HEALTH
B34: Financial RAG (Total Budget): | E34: =L18 -> Watch | F34: Off-Track Budget Lines: | J34: =COUNTIF(L9:L17,"Off Track")&" of "&COUNTA(L9:L17) -> 1 of 9
B35: Technical RAG (Indicator Performance): | E35: =IF(COUNTIF(L23:L30,"Off Track")>0,"Off Track",IF(COUNTIF(L23:L30,"Watch")>0,"Watch","On Track")) -> Off Track | F35: Off-Track Indicators: | J35: =COUNTIF(L23:L30,"Off Track")&" of "&COUNTA(L23:L30) -> 1 of 8
B36: OVERALL PROJECT HEALTH: | E36: =IF(OR(E34="Off Track",E35="Off Track"),"Off Track",IF(OR(E34="Watch",E35="Watch"),"Watch","On Track")) -> Off Track
B38: Programme Manager's Narrative — key achievements, bottlenecks, and corrective actions this month:
B39: Type narrative here...

Sheet CHAP Stawisha
B2: CHAP Stawisha Monthly Performance Monitoring
B4: Donor: | C4: CDC | E4: Reporting Month: | G4: =TODAY() -> 46202 | I4: Project Duration (months): | K4: 12
B5: Project Code: | C5: CHAK/2026/02 | E5: Reporting Period: | G5: Type reporting period here... | I5: Months Elapsed to Date: | K5: 6
B7: SECTION A · FINANCIAL PERFORMANCE — BURN RATE & BUDGET VS. ACTUAL (BVA)
B8: Budget Line | C8: Annual Budget | D8: Planned Cumulative Budget to Date | E8: Actual Cumulative Expenditure to Date | F8: Variance ($) | G8: Variance (%) | H8: Current Month Expenditure | I8: Avg. Monthly Burn Rate | J8: Projected Annual Expenditure | K8: Months Remaining | L8: RAG
B9: Personnel & HR | D9: =C9*$K$5/$K$4 -> 0 | F9: =E9-D9 -> 0 | G9: =IF(D9=0,"N/A",F9/D9) -> N/A | I9: =IF($K$5=0,"N/A",E9/$K$5) -> 0 | J9: =IF(C9=0,"N/A",I9*$K$4) -> N/A | K9: =IF($K$4-$K$5<0,0,$K$4-$K$5) -> 6 | L9: =IF(G9="N/A","N/A",IF(ABS(G9)<=0.1,"On Track",IF(ABS(G9)<=0.2,"Watch","Off Track"))) -> N/A
B10: Technical / Program Activities | D10: =C10*$K$5/$K$4 -> 0 | F10: =E10-D10 -> 0 | G10: =IF(D10=0,"N/A",F10/D10) -> N/A | I10: =IF($K$5=0,"N/A",E10/$K$5) -> 0 | J10: =IF(C10=0,"N/A",I10*$K$4) -> N/A | K10: =IF($K$4-$K$5<0,0,$K$4-$K$5) -> 6 | L10: =IF(G10="N/A","N/A",IF(ABS(G10)<=0.1,"On Track",IF(ABS(G10)<=0.2,"Watch","Off Track"))) -> N/A
B11: Equipment, Supplies & Commodities | D11: =C11*$K$5/$K$4 -> 0 | F11: =E11-D11 -> 0 | G11: =IF(D11=0,"N/A",F11/D11) -> N/A | I11: =IF($K$5=0,"N/A",E11/$K$5) -> 0 | J11: =IF(C11=0,"N/A",I11*$K$4) -> N/A | K11: =IF($K$4-$K$5<0,0,$K$4-$K$5) -> 6 | L11: =IF(G11="N/A","N/A",IF(ABS(G11)<=0.1,"On Track",IF(ABS(G11)<=0.2,"Watch","Off Track"))) -> N/A
B12: Training & Capacity Building | D12: =C12*$K$5/$K$4 -> 0 | F12: =E12-D12 -> 0 | G12: =IF(D12=0,"N/A",F12/D12) -> N/A | I12: =IF($K$5=0,"N/A",E12/$K$5) -> 0 | J12: =IF(C12=0,"N/A",I12*$K$4) -> N/A | K12: =IF($K$4-$K$5<0,0,$K$4-$K$5) -> 6 | L12: =IF(G12="N/A","N/A",IF(ABS(G12)<=0.1,"On Track",IF(ABS(G12)<=0.2,"Watch","Off Track"))) -> N/A
B13: Sub-awards / Partner Disbursements | D13: =C13*$K$5/$K$4 -> 0 | F13: =E13-D13 -> 0 | G13: =IF(D13=0,"N/A",F13/D13) -> N/A | I13: =IF($K$5=0,"N/A",E13/$K$5) -> 0 | J13: =IF(C13=0,"N/A",I13*$K$4) -> N/A | K13: =IF($K$4-$K$5<0,0,$K$4-$K$5) -> 6 | L13: =IF(G13="N/A","N/A",IF(ABS(G13)<=0.1,"On Track",IF(ABS(G13)<=0.2,"Watch","Off Track"))) -> N/A
B14: Monitoring, Evaluation & Learning | D14: =C14*$K$5/$K$4 -> 0 | F14: =E14-D14 -> 0 | G14: =IF(D14=0,"N/A",F14/D14) -> N/A | I14: =IF($K$5=0,"N/A",E14/$K$5) -> 0 | J14: =IF(C14=0,"N/A",I14*$K$4) -> N/A | K14: =IF($K$4-$K$5<0,0,$K$4-$K$5) -> 6 | L14: =IF(G14="N/A","N/A",IF(ABS(G14)<=0.1,"On Track",IF(ABS(G14)<=0.2,"Watch","Off Track"))) -> N/A
B15: Travel & Transport | D15: =C15*$K$5/$K$4 -> 0 | F15: =E15-D15 -> 0 | G15: =IF(D15=0,"N/A",F15/D15) -> N/A | I15: =IF($K$5=0,"N/A",E15/$K$5) -> 0 | J15: =IF(C15=0,"N/A",I15*$K$4) -> N/A | K15: =IF($K$4-$K$5<0,0,$K$4-$K$5) -> 6 | L15: =IF(G15="N/A","N/A",IF(ABS(G15)<=0.1,"On Track",IF(ABS(G15)<=0.2,"Watch","Off Track"))) -> N/A
B16: Administration & Overheads | D16: =C16*$K$5/$K$4 -> 0 | F16: =E16-D16 -> 0 | G16: =IF(D16=0,"N/A",F16/D16) -> N/A | I16: =IF($K$5=0,"N/A",E16/$K$5) -> 0 | J16: =IF(C16=0,"N/A",I16*$K$4) -> N/A | K16: =IF($K$4-$K$5<0,0,$K$4-$K$5) -> 6 | L16: =IF(G16="N/A","N/A",IF(ABS(G16)<=0.1,"On Track",IF(ABS(G16)<=0.2,"Watch","Off Track"))) -> N/A
B17: Other Direct Costs / Contingency | D17: =C17*$K$5/$K$4 -> 0 | F17: =E17-D17 -> 0 | G17: =IF(D17=0,"N/A",F17/D17) -> N/A | I17: =IF($K$5=0,"N/A",E17/$K$5) -> 0 | J17: =IF(C17=0,"N/A",I17*$K$4) -> N/A | K17: =IF($K$4-$K$5<0,0,$K$4-$K$5) -> 6 | L17: =IF(G17="N/A","N/A",IF(ABS(G17)<=0.1,"On Track",IF(ABS(G17)<=0.2,"Watch","Off Track"))) -> N/A
B18: TOTAL PROJECT BUDGET | C18: =SUM(C9:C17) -> 0 | D18: =SUM(D9:D17) -> 0 | E18: =SUM(E9:E17) -> 0 | F18: =E18-D18 -> 0 | G18: =IF(D18=0,"N/A",F18/D18) -> N/A | H18: =SUM(H9:H17) -> 0 | I18: =IF($K$5=0,"N/A",E18/$K$5) -> 0 | J18: =IF(C18=0,"N/A",I18*$K$4) -> N/A | K18: =IF($K$4-$K$5<0,0,$K$4-$K$5) -> 6 | L18: =IF(G18="N/A","N/A",IF(ABS(G18)<=0.1,"On Track",IF(ABS(G18)<=0.2,"Watch","Off Track"))) -> N/A
B19: Planned cumulative budget assumes even (straight-line) spend across the project duration. Variance >20% in either direction triggers Off Track — overspend risks a funding gap; underspend risks an end-of-award absorption/refund issue.
B21: SECTION B · TECHNICAL / DONOR INDICATOR PERFORMANCE
B22: Indicator | C22: Unit / Definition | D22: Annual Target | E22: Planned Cumulative Target to Date | F22: Actual Cumulative Result to Date | G22: Achievement (%) | L22: RAG
B23: Tracer Indicator 1 | C23: Define per donor M&E framework | D23: 500 | E23: =D23*$K$5/$K$4 -> 250 | F23: 125 | G23: =IF(E23=0,"N/A",F23/E23) -> 0.5 | L23: =IF(G23="N/A","N/A",IF(G23>=0.9,"On Track",IF(G23>=0.75,"Watch","Off Track"))) -> Off Track
B24: Tracer Indicator 2 | C24: Define per donor M&E framework | E24: =D24*$K$5/$K$4 -> 0 | G24: =IF(E24=0,"N/A",F24/E24) -> N/A | L24: =IF(G24="N/A","N/A",IF(G24>=0.9,"On Track",IF(G24>=0.75,"Watch","Off Track"))) -> N/A
B25: Tracer Indicator 3 | C25: Define per donor M&E framework | E25: =D25*$K$5/$K$4 -> 0 | G25: =IF(E25=0,"N/A",F25/E25) -> N/A | L25: =IF(G25="N/A","N/A",IF(G25>=0.9,"On Track",IF(G25>=0.75,"Watch","Off Track"))) -> N/A
B26: Tracer Indicator 4 | C26: Define per donor M&E framework | E26: =D26*$K$5/$K$4 -> 0 | G26: =IF(E26=0,"N/A",F26/E26) -> N/A | L26: =IF(G26="N/A","N/A",IF(G26>=0.9,"On Track",IF(G26>=0.75,"Watch","Off Track"))) -> N/A
B27: Tracer Indicator 5 | C27: Define per donor M&E framework | E27: =D27*$K$5/$K$4 -> 0 | G27: =IF(E27=0,"N/A",F27/E27) -> N/A | L27: =IF(G27="N/A","N/A",IF(G27>=0.9,"On Track",IF(G27>=0.75,"Watch","Off Track"))) -> N/A
B28: Tracer Indicator 6 | C28: Define per donor M&E framework | E28: =D28*$K$5/$K$4 -> 0 | G28: =IF(E28=0,"N/A",F28/E28) -> N/A | L28: =IF(G28="N/A","N/A",IF(G28>=0.9,"On Track",IF(G28>=0.75,"Watch","Off Track"))) -> N/A
B29: Tracer Indicator 7 | C29: Define per donor M&E framework | E29: =D29*$K$5/$K$4 -> 0 | G29: =IF(E29=0,"N/A",F29/E29) -> N/A | L29: =IF(G29="N/A","N/A",IF(G29>=0.9,"On Track",IF(G29>=0.75,"Watch","Off Track"))) -> N/A
B30: Tracer Indicator 8 | C30: Define per donor M&E framework | E30: =D30*$K$5/$K$4 -> 0 | G30: =IF(E30=0,"N/A",F30/E30) -> N/A | L30: =IF(G30="N/A","N/A",IF(G30>=0.9,"On Track",IF(G30>=0.75,"Watch","Off Track"))) -> N/A
B31: Indicator names are standard/illustrative donor indicators for this project type — replace with your specific donor's exact indicator list, definitions and reporting frequency where they differ.
B33: SECTION C · OVERALL PROJECT HEALTH
B34: Financial RAG (Total Budget): | E34: =L18 -> N/A | F34: Off-Track Budget Lines: | J34: =COUNTIF(L9:L17,"Off Track")&" of "&COUNTA(L9:L17) -> 0 of 9
B35: Technical RAG (Indicator Performance): | E35: =IF(COUNTIF(L23:L30,"Off Track")>0,"Off Track",IF(COUNTIF(L23:L30,"Watch")>0,"Watch",IF(COUNTIF(L23:L30,"N/A")>0,"N/A","On Track"))) -> Off Track | F35: Off-Track Indicators: | J35: =COUNTIF(L23:L30,"Off Track")&" of "&COUNTA(L23:L30) -> 1 of 8
B36: OVERALL PROJECT HEALTH: | E36: =IF(OR(E34="Off Track",E35="Off Track"),"Off Track",IF(OR(E34="Off Track",E35="On Track"),"Watch",IF(OR(E34="Watch",E35="Watch"),"Watch",IF(OR(E34="On Track",E35="Watch"),"Watch",IF(OR(E34="Watch",E35="On Track"),"Watch",IF(OR(E34="N/A",E35="N/A"),"N/A","On Track")))))) -> Off Track
B38: Programme Manager's Narrative — key achievements, bottlenecks, and corrective actions this month:
B39: Type narrative here...

Sheet Eye Health - ACSP & GitLab
B2: Eye Health (ACSP & GitLab Foundation) Monthly Performance Monitoring
B4: Donor: | C4: ACHAP / GitLab Foundation | E4: Reporting Month: | G4: =TODAY() -> 46202 | I4: Project Duration (months): | K4: 12
B5: Project Code: | C5: CHAK/2026/03 | E5: Reporting Period: | G5: Type reporting period here... | I5: Months Elapsed to Date: | K5: 5
B7: SECTION A · FINANCIAL PERFORMANCE — BURN RATE & BUDGET VS. ACTUAL (BVA)
B8: Budget Line | C8: Annual Budget | D8: Planned Cumulative Budget to Date | E8: Actual Cumulative Expenditure to Date | F8: Variance ($) | G8: Variance (%) | H8: Current Month Expenditure | I8: Avg. Monthly Burn Rate | J8: Projected Annual Expenditure | K8: Months Remaining | L8: RAG
B9: Personnel & HR | C9: 18000000 | D9: =C9*$K$5/$K$4 -> 7500000 | E9: 6750000 | F9: =E9-D9 -> -750000 | G9: =IF(D9=0,"N/A",F9/D9) -> -0.1 | H9: 1350000 | I9: =IF($K$5=0,"N/A",E9/$K$5) -> 1350000 | J9: =IF(C9=0,"N/A",I9*$K$4) -> 16200000 | K9: =IF($K$4-$K$5<0,0,$K$4-$K$5) -> 7 | L9: =IF(G9="N/A","N/A",IF(ABS(G9)<=0.1,"On Track",IF(ABS(G9)<=0.2,"Watch","Off Track"))) -> On Track
B10: Technical / Program Activities | C10: 9000000 | D10: =C10*$K$5/$K$4 -> 3750000 | E10: 3375000 | F10: =E10-D10 -> -375000 | G10: =IF(D10=0,"N/A",F10/D10) -> -0.1 | H10: 675000 | I10: =IF($K$5=0,"N/A",E10/$K$5) -> 675000 | J10: =IF(C10=0,"N/A",I10*$K$4) -> 8100000 | K10: =IF($K$4-$K$5<0,0,$K$4-$K$5) -> 7 | L10: =IF(G10="N/A","N/A",IF(ABS(G10)<=0.1,"On Track",IF(ABS(G10)<=0.2,"Watch","Off Track"))) -> On Track
B11: Equipment, Supplies & Commodities | C11: 7500000 | D11: =C11*$K$5/$K$4 -> 3125000 | E11: 2812500 | F11: =E11-D11 -> -312500 | G11: =IF(D11=0,"N/A",F11/D11) -> -0.1 | H11: 562500 | I11: =IF($K$5=0,"N/A",E11/$K$5) -> 562500 | J11: =IF(C11=0,"N/A",I11*$K$4) -> 6750000 | K11: =IF($K$4-$K$5<0,0,$K$4-$K$5) -> 7 | L11: =IF(G11="N/A","N/A",IF(ABS(G11)<=0.1,"On Track",IF(ABS(G11)<=0.2,"Watch","Off Track"))) -> On Track
B12: Training & Capacity Building | C12: 6000000 | D12: =C12*$K$5/$K$4 -> 2500000 | E12: 2250000 | F12: =E12-D12 -> -250000 | G12: =IF(D12=0,"N/A",F12/D12) -> -0.1 | H12: 450000 | I12: =IF($K$5=0,"N/A",E12/$K$5) -> 450000 | J12: =IF(C12=0,"N/A",I12*$K$4) -> 5400000 | K12: =IF($K$4-$K$5<0,0,$K$4-$K$5) -> 7 | L12: =IF(G12="N/A","N/A",IF(ABS(G12)<=0.1,"On Track",IF(ABS(G12)<=0.2,"Watch","Off Track"))) -> On Track
B13: Sub-awards / Partner Disbursements | C13: 9500000 | D13: =C13*$K$5/$K$4 -> 3958333.3 | E13: 3562500 | F13: =E13-D13 -> -395833.33 | G13: =IF(D13=0,"N/A",F13/D13) -> -0.1 | H13: 712500 | I13: =IF($K$5=0,"N/A",E13/$K$5) -> 712500 | J13: =IF(C13=0,"N/A",I13*$K$4) -> 8550000 | K13: =IF($K$4-$K$5<0,0,$K$4-$K$5) -> 7 | L13: =IF(G13="N/A","N/A",IF(ABS(G13)<=0.1,"On Track",IF(ABS(G13)<=0.2,"Watch","Off Track"))) -> On Track
B14: Monitoring, Evaluation & Learning | C14: 4000000 | D14: =C14*$K$5/$K$4 -> 1666666.7 | E14: 1500000 | F14: =E14-D14 -> -166666.67 | G14: =IF(D14=0,"N/A",F14/D14) -> -0.1 | H14: 300000 | I14: =IF($K$5=0,"N/A",E14/$K$5) -> 300000 | J14: =IF(C14=0,"N/A",I14*$K$4) -> 3600000 | K14: =IF($K$4-$K$5<0,0,$K$4-$K$5) -> 7 | L14: =IF(G14="N/A","N/A",IF(ABS(G14)<=0.1,"On Track",IF(ABS(G14)<=0.2,"Watch","Off Track"))) -> On Track
B15: Travel & Transport | C15: 6500000 | D15: =C15*$K$5/$K$4 -> 2708333.3 | E15: 2437500 | F15: =E15-D15 -> -270833.33 | G15: =IF(D15=0,"N/A",F15/D15) -> -0.1 | H15: 487500 | I15: =IF($K$5=0,"N/A",E15/$K$5) -> 487500 | J15: =IF(C15=0,"N/A",I15*$K$4) -> 5850000 | K15: =IF($K$4-$K$5<0,0,$K$4-$K$5) -> 7 | L15: =IF(G15="N/A","N/A",IF(ABS(G15)<=0.1,"On Track",IF(ABS(G15)<=0.2,"Watch","Off Track"))) -> On Track
B16: Administration & Overheads | C16: 3000000 | D16: =C16*$K$5/$K$4 -> 1250000 | E16: 1125000 | F16: =E16-D16 -> -125000 | G16: =IF(D16=0,"N/A",F16/D16) -> -0.1 | H16: 225000 | I16: =IF($K$5=0,"N/A",E16/$K$5) -> 225000 | J16: =IF(C16=0,"N/A",I16*$K$4) -> 2700000 | K16: =IF($K$4-$K$5<0,0,$K$4-$K$5) -> 7 | L16: =IF(G16="N/A","N/A",IF(ABS(G16)<=0.1,"On Track",IF(ABS(G16)<=0.2,"Watch","Off Track"))) -> On Track
B17: Other Direct Costs / Contingency | C17: 5000000 | D17: =C17*$K$5/$K$4 -> 2083333.3 | E17: 1875000 | F17: =E17-D17 -> -208333.33 | G17: =IF(D17=0,"N/A",F17/D17) -> -0.1 | H17: 375000 | I17: =IF($K$5=0,"N/A",E17/$K$5) -> 375000 | J17: =IF(C17=0,"N/A",I17*$K$4) -> 4500000 | K17: =IF($K$4-$K$5<0,0,$K$4-$K$5) -> 7 | L17: =IF(G17="N/A","N/A",IF(ABS(G17)<=0.1,"On Track",IF(ABS(G17)<=0.2,"Watch","Off Track"))) -> On Track
B18: TOTAL PROJECT BUDGET | C18: =SUM(C9:C17) -> 68500000 | D18: =SUM(D9:D17) -> 28541667 | E18: =SUM(E9:E17) -> 25687500 | F18: =E18-D18 -> -2854166.7 | G18: =IF(D18=0,"N/A",F18/D18) -> -0.1 | H18: =SUM(H9:H17) -> 5137500 | I18: =IF($K$5=0,"N/A",E18/$K$5) -> 5137500 | J18: =IF(C18=0,"N/A",I18*$K$4) -> 61650000 | K18: =IF($K$4-$K$5<0,0,$K$4-$K$5) -> 7 | L18: =IF(G18="N/A","N/A",IF(ABS(G18)<=0.1,"On Track",IF(ABS(G18)<=0.2,"Watch","Off Track"))) -> On Track
B19: Planned cumulative budget assumes even (straight-line) spend across the project duration. Variance >20% in either direction triggers Off Track — overspend risks a funding gap; underspend risks an end-of-award absorption/refund issue.
B21: SECTION B · TECHNICAL / DONOR INDICATOR PERFORMANCE
B22: Indicator | C22: Unit / Definition | D22: Annual Target | E22: Planned Cumulative Target to Date | F22: Actual Cumulative Result to Date | G22: Achievement (%) | L22: RAG
B23: Tracer Indicator 1 | C23: Define per donor M&E framework | D23: 1200 | E23: =D23*$K$5/$K$4 -> 500 | F23: 460 | G23: =IF(E23=0,"N/A",F23/E23) -> 0.92 | L23: =IF(G23="N/A","N/A",IF(G23>=0.9,"On Track",IF(G23>=0.75,"Watch","Off Track"))) -> On Track
B24: Tracer Indicator 2 | C24: Define per donor M&E framework | D24: 600 | E24: =D24*$K$5/$K$4 -> 250 | F24: 230 | G24: =IF(E24=0,"N/A",F24/E24) -> 0.92 | L24: =IF(G24="N/A","N/A",IF(G24>=0.9,"On Track",IF(G24>=0.75,"Watch","Off Track"))) -> On Track
B25: Tracer Indicator 3 | C25: Define per donor M&E framework | D25: 900 | E25: =D25*$K$5/$K$4 -> 375 | F25: 345 | G25: =IF(E25=0,"N/A",F25/E25) -> 0.92 | L25: =IF(G25="N/A","N/A",IF(G25>=0.9,"On Track",IF(G25>=0.75,"Watch","Off Track"))) -> On Track
B26: Tracer Indicator 4 | C26: Define per donor M&E framework | D26: 450 | E26: =D26*$K$5/$K$4 -> 187.5 | F26: 172 | G26: =IF(E26=0,"N/A",F26/E26) -> 0.91733333 | L26: =IF(G26="N/A","N/A",IF(G26>=0.9,"On Track",IF(G26>=0.75,"Watch","Off Track"))) -> On Track
B27: Tracer Indicator 5 | C27: Define per donor M&E framework | D27: 1500 | E27: =D27*$K$5/$K$4 -> 625 | F27: 575 | G27: =IF(E27=0,"N/A",F27/E27) -> 0.92 | L27: =IF(G27="N/A","N/A",IF(G27>=0.9,"On Track",IF(G27>=0.75,"Watch","Off Track"))) -> On Track
B28: Tracer Indicator 6 | C28: Define per donor M&E framework | D28: 300 | E28: =D28*$K$5/$K$4 -> 125 | F28: 115 | G28: =IF(E28=0,"N/A",F28/E28) -> 0.92 | L28: =IF(G28="N/A","N/A",IF(G28>=0.9,"On Track",IF(G28>=0.75,"Watch","Off Track"))) -> On Track
B29: Tracer Indicator 7 | C29: Define per donor M&E framework | D29: 750 | E29: =D29*$K$5/$K$4 -> 312.5 | F29: 288 | G29: =IF(E29=0,"N/A",F29/E29) -> 0.9216 | L29: =IF(G29="N/A","N/A",IF(G29>=0.9,"On Track",IF(G29>=0.75,"Watch","Off Track"))) -> On Track
B30: Tracer Indicator 8 | C30: Define per donor M&E framework | D30: 200 | E30: =D30*$K$5/$K$4 -> 83.333333 | F30: 77 | G30: =IF(E30=0,"N/A",F30/E30) -> 0.924 | L30: =IF(G30="N/A","N/A",IF(G30>=0.9,"On Track",IF(G30>=0.75,"Watch","Off Track"))) -> On Track
B31: Indicator names are standard/illustrative donor indicators for this project type — replace with your specific donor's exact indicator list, definitions and reporting frequency where they differ.
B33: SECTION C · OVERALL PROJECT HEALTH
B34: Financial RAG (Total Budget): | E34: =L18 -> On Track | F34: Off-Track Budget Lines: | J34: =COUNTIF(L9:L17,"Off Track")&" of "&COUNTA(L9:L17) -> 0 of 9
B35: Technical RAG (Indicator Performance): | E35: =IF(COUNTIF(L23:L30,"Off Track")>0,"Off Track",IF(COUNTIF(L23:L30,"Watch")>0,"Watch","On Track")) -> On Track | F35: Off-Track Indicators: | J35: =COUNTIF(L23:L30,"Off Track")&" of "&COUNTA(L23:L30) -> 0 of 8
B36: OVERALL PROJECT HEALTH: | E36: =IF(OR(E34="Off Track",E35="Off Track"),"Off Track",IF(OR(E34="Watch",E35="Watch"),"Watch","On Track")) -> On Track
B38: Programme Manager's Narrative — key achievements, bottlenecks, and corrective actions this month:
B39: Type narrative here...

Sheet EIS
B2: Evaluation of Integrated Services (EIS) Monthly Performance Monitoring
B4: Donor: | C4: Bill & Melinda Gates Foundation | E4: Reporting Month: | G4: =TODAY() -> 46202 | I4: Project Duration (months): | K4: 24
B5: Project Code: | C5: CHAK/2026/04 | E5: Reporting Period: | G5: Type reporting period here... | I5: Months Elapsed to Date: | K5: 10
B7: SECTION A · FINANCIAL PERFORMANCE — BURN RATE & BUDGET VS. ACTUAL (BVA)
B8: Budget Line | C8: Annual Budget | D8: Planned Cumulative Budget to Date | E8: Actual Cumulative Expenditure to Date | F8: Variance ($) | G8: Variance (%) | H8: Current Month Expenditure | I8: Avg. Monthly Burn Rate | J8: Projected Annual Expenditure | K8: Months Remaining | L8: RAG
B9: Personnel & HR | C9: 18000000 | D9: =C9*$K$5/$K$4 -> 7500000 | E9: 9375000 | F9: =E9-D9 -> 1875000 | G9: =IF(D9=0,"N/A",F9/D9) -> 0.25 | H9: 937500 | I9: =IF($K$5=0,"N/A",E9/$K$5) -> 937500 | J9: =IF(C9=0,"N/A",I9*$K$4) -> 22500000 | K9: =IF($K$4-$K$5<0,0,$K$4-$K$5) -> 14 | L9: =IF(G9="N/A","N/A",IF(ABS(G9)<=0.1,"On Track",IF(ABS(G9)<=0.2,"Watch","Off Track"))) -> Off Track
B10: Technical / Program Activities | C10: 9000000 | D10: =C10*$K$5/$K$4 -> 3750000 | E10: 4687500 | F10: =E10-D10 -> 937500 | G10: =IF(D10=0,"N/A",F10/D10) -> 0.25 | H10: 468750 | I10: =IF($K$5=0,"N/A",E10/$K$5) -> 468750 | J10: =IF(C10=0,"N/A",I10*$K$4) -> 11250000 | K10: =IF($K$4-$K$5<0,0,$K$4-$K$5) -> 14 | L10: =IF(G10="N/A","N/A",IF(ABS(G10)<=0.1,"On Track",IF(ABS(G10)<=0.2,"Watch","Off Track"))) -> Off Track
B11: Equipment, Supplies & Commodities | C11: 7500000 | D11: =C11*$K$5/$K$4 -> 3125000 | E11: 3906250 | F11: =E11-D11 -> 781250 | G11: =IF(D11=0,"N/A",F11/D11) -> 0.25 | H11: 390625 | I11: =IF($K$5=0,"N/A",E11/$K$5) -> 390625 | J11: =IF(C11=0,"N/A",I11*$K$4) -> 9375000 | K11: =IF($K$4-$K$5<0,0,$K$4-$K$5) -> 14 | L11: =IF(G11="N/A","N/A",IF(ABS(G11)<=0.1,"On Track",IF(ABS(G11)<=0.2,"Watch","Off Track"))) -> Off Track
B12: Training & Capacity Building | C12: 6000000 | D12: =C12*$K$5/$K$4 -> 2500000 | E12: 3125000 | F12: =E12-D12 -> 625000 | G12: =IF(D12=0,"N/A",F12/D12) -> 0.25 | H12: 312500 | I12: =IF($K$5=0,"N/A",E12/$K$5) -> 312500 | J12: =IF(C12=0,"N/A",I12*$K$4) -> 7500000 | K12: =IF($K$4-$K$5<0,0,$K$4-$K$5) -> 14 | L12: =IF(G12="N/A","N/A",IF(ABS(G12)<=0.1,"On Track",IF(ABS(G12)<=0.2,"Watch","Off Track"))) -> Off Track
B13: Sub-awards / Partner Disbursements | C13: 9500000 | D13: =C13*$K$5/$K$4 -> 3958333.3 | E13: 4947917 | F13: =E13-D13 -> 989583.67 | G13: =IF(D13=0,"N/A",F13/D13) -> 0.25000008 | H13: 494792 | I13: =IF($K$5=0,"N/A",E13/$K$5) -> 494791.7 | J13: =IF(C13=0,"N/A",I13*$K$4) -> 11875001 | K13: =IF($K$4-$K$5<0,0,$K$4-$K$5) -> 14 | L13: =IF(G13="N/A","N/A",IF(ABS(G13)<=0.1,"On Track",IF(ABS(G13)<=0.2,"Watch","Off Track"))) -> Off Track
B14: Monitoring, Evaluation & Learning | C14: 4000000 | D14: =C14*$K$5/$K$4 -> 1666666.7 | E14: 2083333 | F14: =E14-D14 -> 416666.33 | G14: =IF(D14=0,"N/A",F14/D14) -> 0.2499998 | H14: 208333 | I14: =IF($K$5=0,"N/A",E14/$K$5) -> 208333.3 | J14: =IF(C14=0,"N/A",I14*$K$4) -> 4999999.2 | K14: =IF($K$4-$K$5<0,0,$K$4-$K$5) -> 14 | L14: =IF(G14="N/A","N/A",IF(ABS(G14)<=0.1,"On Track",IF(ABS(G14)<=0.2,"Watch","Off Track"))) -> Off Track
B15: Travel & Transport | C15: 6500000 | D15: =C15*$K$5/$K$4 -> 2708333.3 | E15: 3385417 | F15: =E15-D15 -> 677083.67 | G15: =IF(D15=0,"N/A",F15/D15) -> 0.25000012 | H15: 338542 | I15: =IF($K$5=0,"N/A",E15/$K$5) -> 338541.7 | J15: =IF(C15=0,"N/A",I15*$K$4) -> 8125000.8 | K15: =IF($K$4-$K$5<0,0,$K$4-$K$5) -> 14 | L15: =IF(G15="N/A","N/A",IF(ABS(G15)<=0.1,"On Track",IF(ABS(G15)<=0.2,"Watch","Off Track"))) -> Off Track
B16: Administration & Overheads | C16: 3000000 | D16: =C16*$K$5/$K$4 -> 1250000 | E16: 1562500 | F16: =E16-D16 -> 312500 | G16: =IF(D16=0,"N/A",F16/D16) -> 0.25 | H16: 156250 | I16: =IF($K$5=0,"N/A",E16/$K$5) -> 156250 | J16: =IF(C16=0,"N/A",I16*$K$4) -> 3750000 | K16: =IF($K$4-$K$5<0,0,$K$4-$K$5) -> 14 | L16: =IF(G16="N/A","N/A",IF(ABS(G16)<=0.1,"On Track",IF(ABS(G16)<=0.2,"Watch","Off Track"))) -> Off Track
B17: Other Direct Costs / Contingency | C17: 5000000 | D17: =C17*$K$5/$K$4 -> 2083333.3 | E17: 2604167 | F17: =E17-D17 -> 520833.67 | G17: =IF(D17=0,"N/A",F17/D17) -> 0.25000016 | H17: 260417 | I17: =IF($K$5=0,"N/A",E17/$K$5) -> 260416.7 | J17: =IF(C17=0,"N/A",I17*$K$4) -> 6250000.8 | K17: =IF($K$4-$K$5<0,0,$K$4-$K$5) -> 14 | L17: =IF(G17="N/A","N/A",IF(ABS(G17)<=0.1,"On Track",IF(ABS(G17)<=0.2,"Watch","Off Track"))) -> Off Track
B18: TOTAL PROJECT BUDGET | C18: =SUM(C9:C17) -> 68500000 | D18: =SUM(D9:D17) -> 28541667 | E18: =SUM(E9:E17) -> 35677084 | F18: =E18-D18 -> 7135417.3 | G18: =IF(D18=0,"N/A",F18/D18) -> 0.25000002 | H18: =SUM(H9:H17) -> 3567709 | I18: =IF($K$5=0,"N/A",E18/$K$5) -> 3567708.4 | J18: =IF(C18=0,"N/A",I18*$K$4) -> 85625002 | K18: =IF($K$4-$K$5<0,0,$K$4-$K$5) -> 14 | L18: =IF(G18="N/A","N/A",IF(ABS(G18)<=0.1,"On Track",IF(ABS(G18)<=0.2,"Watch","Off Track"))) -> Off Track
B19: Planned cumulative budget assumes even (straight-line) spend across the project duration. Variance >20% in either direction triggers Off Track — overspend risks a funding gap; underspend risks an end-of-award absorption/refund issue.
B21: SECTION B · TECHNICAL / DONOR INDICATOR PERFORMANCE
B22: Indicator | C22: Unit / Definition | D22: Annual Target | E22: Planned Cumulative Target to Date | F22: Actual Cumulative Result to Date | G22: Achievement (%) | L22: RAG
B23: Tracer Indicator 1 | C23: Define per donor M&E framework | D23: 1200 | E23: =D23*$K$5/$K$4 -> 500 | F23: 350 | G23: =IF(E23=0,"N/A",F23/E23) -> 0.7 | L23: =IF(G23="N/A","N/A",IF(G23>=0.9,"On Track",IF(G23>=0.75,"Watch","Off Track"))) -> Off Track
B24: Tracer Indicator 2 | C24: Define per donor M&E framework | D24: 600 | E24: =D24*$K$5/$K$4 -> 250 | F24: 175 | G24: =IF(E24=0,"N/A",F24/E24) -> 0.7 | L24: =IF(G24="N/A","N/A",IF(G24>=0.9,"On Track",IF(G24>=0.75,"Watch","Off Track"))) -> Off Track
B25: Tracer Indicator 3 | C25: Define per donor M&E framework | D25: 900 | E25: =D25*$K$5/$K$4 -> 375 | F25: 262 | G25: =IF(E25=0,"N/A",F25/E25) -> 0.69866667 | L25: =IF(G25="N/A","N/A",IF(G25>=0.9,"On Track",IF(G25>=0.75,"Watch","Off Track"))) -> Off Track
B26: Tracer Indicator 4 | C26: Define per donor M&E framework | D26: 450 | E26: =D26*$K$5/$K$4 -> 187.5 | F26: 131 | G26: =IF(E26=0,"N/A",F26/E26) -> 0.69866667 | L26: =IF(G26="N/A","N/A",IF(G26>=0.9,"On Track",IF(G26>=0.75,"Watch","Off Track"))) -> Off Track
B27: Tracer Indicator 5 | C27: Define per donor M&E framework | D27: 1500 | E27: =D27*$K$5/$K$4 -> 625 | F27: 438 | G27: =IF(E27=0,"N/A",F27/E27) -> 0.7008 | L27: =IF(G27="N/A","N/A",IF(G27>=0.9,"On Track",IF(G27>=0.75,"Watch","Off Track"))) -> Off Track
B28: Tracer Indicator 6 | C28: Define per donor M&E framework | D28: 300 | E28: =D28*$K$5/$K$4 -> 125 | F28: 88 | G28: =IF(E28=0,"N/A",F28/E28) -> 0.704 | L28: =IF(G28="N/A","N/A",IF(G28>=0.9,"On Track",IF(G28>=0.75,"Watch","Off Track"))) -> Off Track
B29: Tracer Indicator 7 | C29: Define per donor M&E framework | D29: 750 | E29: =D29*$K$5/$K$4 -> 312.5 | F29: 219 | G29: =IF(E29=0,"N/A",F29/E29) -> 0.7008 | L29: =IF(G29="N/A","N/A",IF(G29>=0.9,"On Track",IF(G29>=0.75,"Watch","Off Track"))) -> Off Track
B30: Tracer Indicator 8 | C30: Define per donor M&E framework | D30: 200 | E30: =D30*$K$5/$K$4 -> 83.333333 | F30: 58 | G30: =IF(E30=0,"N/A",F30/E30) -> 0.696 | L30: =IF(G30="N/A","N/A",IF(G30>=0.9,"On Track",IF(G30>=0.75,"Watch","Off Track"))) -> Off Track
B31: Indicator names are standard/illustrative donor indicators for this project type — replace with your specific donor's exact indicator list, definitions and reporting frequency where they differ.
B33: SECTION C · OVERALL PROJECT HEALTH
B34: Financial RAG (Total Budget): | E34: =L18 -> Off Track | F34: Off-Track Budget Lines: | J34: =COUNTIF(L9:L17,"Off Track")&" of "&COUNTA(L9:L17) -> 9 of 9
B35: Technical RAG (Indicator Performance): | E35: =IF(COUNTIF(L23:L30,"Off Track")>0,"Off Track",IF(COUNTIF(L23:L30,"Watch")>0,"Watch","On Track")) -> Off Track | F35: Off-Track Indicators: | J35: =COUNTIF(L23:L30,"Off Track")&" of "&COUNTA(L23:L30) -> 8 of 8
B36: OVERALL PROJECT HEALTH: | E36: =IF(OR(E34="Off Track",E35="Off Track"),"Off Track",IF(OR(E34="Watch",E35="Watch"),"Watch","On Track")) -> Off Track
B38: Programme Manager's Narrative — key achievements, bottlenecks, and corrective actions this month:
B39: Type narrative here...

Sheet BFTW HSS
B2: BFTW - HSS Monthly Performance Monitoring
B4: Donor: | C4: Bread for the World | E4: Reporting Month: | G4: =TODAY() -> 46202 | I4: Project Duration (months): | K4: 12
B5: Project Code: | C5: CHAK/2026/05 | E5: Reporting Period: | G5: Type reporting period here... | I5: Months Elapsed to Date: | K5: 5
B7: SECTION A · FINANCIAL PERFORMANCE — BURN RATE & BUDGET VS. ACTUAL (BVA)
B8: Budget Line | C8: Annual Budget | D8: Planned Cumulative Budget to Date | E8: Actual Cumulative Expenditure to Date | F8: Variance ($) | G8: Variance (%) | H8: Current Month Expenditure | I8: Avg. Monthly Burn Rate | J8: Projected Annual Expenditure | K8: Months Remaining | L8: RAG
B9: Personnel & HR | C9: 18000000 | D9: =C9*$K$5/$K$4 -> 7500000 | E9: 7275000 | F9: =E9-D9 -> -225000 | G9: =IF(D9=0,"N/A",F9/D9) -> -0.03 | H9: 1455000 | I9: =IF($K$5=0,"N/A",E9/$K$5) -> 1455000 | J9: =IF(C9=0,"N/A",I9*$K$4) -> 17460000 | K9: =IF($K$4-$K$5<0,0,$K$4-$K$5) -> 7 | L9: =IF(G9="N/A","N/A",IF(ABS(G9)<=0.1,"On Track",IF(ABS(G9)<=0.2,"Watch","Off Track"))) -> On Track
B10: Technical / Program Activities | C10: 9000000 | D10: =C10*$K$5/$K$4 -> 3750000 | E10: 3637500 | F10: =E10-D10 -> -112500 | G10: =IF(D10=0,"N/A",F10/D10) -> -0.03 | H10: 727500 | I10: =IF($K$5=0,"N/A",E10/$K$5) -> 727500 | J10: =IF(C10=0,"N/A",I10*$K$4) -> 8730000 | K10: =IF($K$4-$K$5<0,0,$K$4-$K$5) -> 7 | L10: =IF(G10="N/A","N/A",IF(ABS(G10)<=0.1,"On Track",IF(ABS(G10)<=0.2,"Watch","Off Track"))) -> On Track
B11: Equipment, Supplies & Commodities | C11: 7500000 | D11: =C11*$K$5/$K$4 -> 3125000 | E11: 3031250 | F11: =E11-D11 -> -93750 | G11: =IF(D11=0,"N/A",F11/D11) -> -0.03 | H11: 606250 | I11: =IF($K$5=0,"N/A",E11/$K$5) -> 606250 | J11: =IF(C11=0,"N/A",I11*$K$4) -> 7275000 | K11: =IF($K$4-$K$5<0,0,$K$4-$K$5) -> 7 | L11: =IF(G11="N/A","N/A",IF(ABS(G11)<=0.1,"On Track",IF(ABS(G11)<=0.2,"Watch","Off Track"))) -> On Track
B12: Training & Capacity Building | C12: 6000000 | D12: =C12*$K$5/$K$4 -> 2500000 | E12: 2425000 | F12: =E12-D12 -> -75000 | G12: =IF(D12=0,"N/A",F12/D12) -> -0.03 | H12: 485000 | I12: =IF($K$5=0,"N/A",E12/$K$5) -> 485000 | J12: =IF(C12=0,"N/A",I12*$K$4) -> 5820000 | K12: =IF($K$4-$K$5<0,0,$K$4-$K$5) -> 7 | L12: =IF(G12="N/A","N/A",IF(ABS(G12)<=0.1,"On Track",IF(ABS(G12)<=0.2,"Watch","Off Track"))) -> On Track
B13: Sub-awards / Partner Disbursements | C13: 9500000 | D13: =C13*$K$5/$K$4 -> 3958333.3 | E13: 3839583 | F13: =E13-D13 -> -118750.33 | G13: =IF(D13=0,"N/A",F13/D13) -> -0.030000084 | H13: 767917 | I13: =IF($K$5=0,"N/A",E13/$K$5) -> 767916.6 | J13: =IF(C13=0,"N/A",I13*$K$4) -> 9214999.2 | K13: =IF($K$4-$K$5<0,0,$K$4-$K$5) -> 7 | L13: =IF(G13="N/A","N/A",IF(ABS(G13)<=0.1,"On Track",IF(ABS(G13)<=0.2,"Watch","Off Track"))) -> On Track
B14: Monitoring, Evaluation & Learning | C14: 4000000 | D14: =C14*$K$5/$K$4 -> 1666666.7 | E14: 1616667 | F14: =E14-D14 -> -49999.667 | G14: =IF(D14=0,"N/A",F14/D14) -> -0.0299998 | H14: 323333 | I14: =IF($K$5=0,"N/A",E14/$K$5) -> 323333.4 | J14: =IF(C14=0,"N/A",I14*$K$4) -> 3880000.8 | K14: =IF($K$4-$K$5<0,0,$K$4-$K$5) -> 7 | L14: =IF(G14="N/A","N/A",IF(ABS(G14)<=0.1,"On Track",IF(ABS(G14)<=0.2,"Watch","Off Track"))) -> On Track
B15: Travel & Transport | C15: 6500000 | D15: =C15*$K$5/$K$4 -> 2708333.3 | E15: 2627083 | F15: =E15-D15 -> -81250.333 | G15: =IF(D15=0,"N/A",F15/D15) -> -0.030000123 | H15: 525417 | I15: =IF($K$5=0,"N/A",E15/$K$5) -> 525416.6 | J15: =IF(C15=0,"N/A",I15*$K$4) -> 6304999.2 | K15: =IF($K$4-$K$5<0,0,$K$4-$K$5) -> 7 | L15: =IF(G15="N/A","N/A",IF(ABS(G15)<=0.1,"On Track",IF(ABS(G15)<=0.2,"Watch","Off Track"))) -> On Track
B16: Administration & Overheads | C16: 3000000 | D16: =C16*$K$5/$K$4 -> 1250000 | E16: 1212500 | F16: =E16-D16 -> -37500 | G16: =IF(D16=0,"N/A",F16/D16) -> -0.03 | H16: 242500 | I16: =IF($K$5=0,"N/A",E16/$K$5) -> 242500 | J16: =IF(C16=0,"N/A",I16*$K$4) -> 2910000 | K16: =IF($K$4-$K$5<0,0,$K$4-$K$5) -> 7 | L16: =IF(G16="N/A","N/A",IF(ABS(G16)<=0.1,"On Track",IF(ABS(G16)<=0.2,"Watch","Off Track"))) -> On Track
B17: Other Direct Costs / Contingency | C17: 5000000 | D17: =C17*$K$5/$K$4 -> 2083333.3 | E17: 2020833 | F17: =E17-D17 -> -62500.333 | G17: =IF(D17=0,"N/A",F17/D17) -> -0.03000016 | H17: 404167 | I17: =IF($K$5=0,"N/A",E17/$K$5) -> 404166.6 | J17: =IF(C17=0,"N/A",I17*$K$4) -> 4849999.2 | K17: =IF($K$4-$K$5<0,0,$K$4-$K$5) -> 7 | L17: =IF(G17="N/A","N/A",IF(ABS(G17)<=0.1,"On Track",IF(ABS(G17)<=0.2,"Watch","Off Track"))) -> On Track
B18: TOTAL PROJECT BUDGET | C18: =SUM(C9:C17) -> 68500000 | D18: =SUM(D9:D17) -> 28541667 | E18: =SUM(E9:E17) -> 27685416 | F18: =E18-D18 -> -856250.67 | G18: =IF(D18=0,"N/A",F18/D18) -> -0.030000023 | H18: =SUM(H9:H17) -> 5537084 | I18: =IF($K$5=0,"N/A",E18/$K$5) -> 5537083.2 | J18: =IF(C18=0,"N/A",I18*$K$4) -> 66444998 | K18: =IF($K$4-$K$5<0,0,$K$4-$K$5) -> 7 | L18: =IF(G18="N/A","N/A",IF(ABS(G18)<=0.1,"On Track",IF(ABS(G18)<=0.2,"Watch","Off Track"))) -> On Track
B19: Planned cumulative budget assumes even (straight-line) spend across the project duration. Variance >20% in either direction triggers Off Track — overspend risks a funding gap; underspend risks an end-of-award absorption/refund issue.
B21: SECTION B · TECHNICAL / DONOR INDICATOR PERFORMANCE
B22: Indicator | C22: Unit / Definition | D22: Annual Target | E22: Planned Cumulative Target to Date | F22: Actual Cumulative Result to Date | G22: Achievement (%) | L22: RAG
B23: Tracer Indicator 1 | C23: Define per donor M&E framework | D23: 1200 | E23: =D23*$K$5/$K$4 -> 500 | F23: 440 | G23: =IF(E23=0,"N/A",F23/E23) -> 0.88 | L23: =IF(G23="N/A","N/A",IF(G23>=0.9,"On Track",IF(G23>=0.75,"Watch","Off Track"))) -> Watch
B24: Tracer Indicator 2 | C24: Define per donor M&E framework | D24: 600 | E24: =D24*$K$5/$K$4 -> 250 | F24: 220 | G24: =IF(E24=0,"N/A",F24/E24) -> 0.88 | L24: =IF(G24="N/A","N/A",IF(G24>=0.9,"On Track",IF(G24>=0.75,"Watch","Off Track"))) -> Watch
B25: Tracer Indicator 3 | C25: Define per donor M&E framework | D25: 900 | E25: =D25*$K$5/$K$4 -> 375 | F25: 330 | G25: =IF(E25=0,"N/A",F25/E25) -> 0.88 | L25: =IF(G25="N/A","N/A",IF(G25>=0.9,"On Track",IF(G25>=0.75,"Watch","Off Track"))) -> Watch
B26: Tracer Indicator 4 | C26: Define per donor M&E framework | D26: 450 | E26: =D26*$K$5/$K$4 -> 187.5 | F26: 165 | G26: =IF(E26=0,"N/A",F26/E26) -> 0.88 | L26: =IF(G26="N/A","N/A",IF(G26>=0.9,"On Track",IF(G26>=0.75,"Watch","Off Track"))) -> Watch
B27: Tracer Indicator 5 | C27: Define per donor M&E framework | D27: 1500 | E27: =D27*$K$5/$K$4 -> 625 | F27: 550 | G27: =IF(E27=0,"N/A",F27/E27) -> 0.88 | L27: =IF(G27="N/A","N/A",IF(G27>=0.9,"On Track",IF(G27>=0.75,"Watch","Off Track"))) -> Watch
B28: Tracer Indicator 6 | C28: Define per donor M&E framework | D28: 300 | E28: =D28*$K$5/$K$4 -> 125 | F28: 110 | G28: =IF(E28=0,"N/A",F28/E28) -> 0.88 | L28: =IF(G28="N/A","N/A",IF(G28>=0.9,"On Track",IF(G28>=0.75,"Watch","Off Track"))) -> Watch
B29: Tracer Indicator 7 | C29: Define per donor M&E framework | D29: 750 | E29: =D29*$K$5/$K$4 -> 312.5 | F29: 275 | G29: =IF(E29=0,"N/A",F29/E29) -> 0.88 | L29: =IF(G29="N/A","N/A",IF(G29>=0.9,"On Track",IF(G29>=0.75,"Watch","Off Track"))) -> Watch
B30: Tracer Indicator 8 | C30: Define per donor M&E framework | D30: 200 | E30: =D30*$K$5/$K$4 -> 83.333333 | F30: 73 | G30: =IF(E30=0,"N/A",F30/E30) -> 0.876 | L30: =IF(G30="N/A","N/A",IF(G30>=0.9,"On Track",IF(G30>=0.75,"Watch","Off Track"))) -> Watch
B31: Indicator names are standard/illustrative donor indicators for this project type — replace with your specific donor's exact indicator list, definitions and reporting frequency where they differ.
B33: SECTION C · OVERALL PROJECT HEALTH
B34: Financial RAG (Total Budget): | E34: =L18 -> On Track | F34: Off-Track Budget Lines: | J34: =COUNTIF(L9:L17,"Off Track")&" of "&COUNTA(L9:L17) -> 0 of 9
B35: Technical RAG (Indicator Performance): | E35: =IF(COUNTIF(L23:L30,"Off Track")>0,"Off Track",IF(COUNTIF(L23:L30,"Watch")>0,"Watch","On Track")) -> Watch | F35: Off-Track Indicators: | J35: =COUNTIF(L23:L30,"Off Track")&" of "&COUNTA(L23:L30) -> 0 of 8
B36: OVERALL PROJECT HEALTH: | E36: =IF(OR(E34="Off Track",E35="Off Track"),"Off Track",IF(OR(E34="Watch",E35="Watch"),"Watch","On Track")) -> Watch
B38: Programme Manager's Narrative — key achievements, bottlenecks, and corrective actions this month:
B39: Type narrative here...

Sheet BFTW RMNCAH
B2: BFTW - RMNCAH Monthly Performance Monitoring
B4: Donor: | C4: Bread for the World | E4: Reporting Month: | G4: =TODAY() -> 46202 | I4: Project Duration (months): | K4: 12
B5: Project Code: | C5: CHAK/2026/06 | E5: Reporting Period: | G5: Type reporting period here... | I5: Months Elapsed to Date: | K5: 5
B7: SECTION A · FINANCIAL PERFORMANCE — BURN RATE & BUDGET VS. ACTUAL (BVA)
B8: Budget Line | C8: Annual Budget | D8: Planned Cumulative Budget to Date | E8: Actual Cumulative Expenditure to Date | F8: Variance ($) | G8: Variance (%) | H8: Current Month Expenditure | I8: Avg. Monthly Burn Rate | J8: Projected Annual Expenditure | K8: Months Remaining | L8: RAG
B9: Personnel & HR | C9: 18000000 | D9: =C9*$K$5/$K$4 -> 7500000 | E9: 7875000 | F9: =E9-D9 -> 375000 | G9: =IF(D9=0,"N/A",F9/D9) -> 0.05 | H9: 1575000 | I9: =IF($K$5=0,"N/A",E9/$K$5) -> 1575000 | J9: =IF(C9=0,"N/A",I9*$K$4) -> 18900000 | K9: =IF($K$4-$K$5<0,0,$K$4-$K$5) -> 7 | L9: =IF(G9="N/A","N/A",IF(ABS(G9)<=0.1,"On Track",IF(ABS(G9)<=0.2,"Watch","Off Track"))) -> On Track
B10: Technical / Program Activities | C10: 9000000 | D10: =C10*$K$5/$K$4 -> 3750000 | E10: 3937500 | F10: =E10-D10 -> 187500 | G10: =IF(D10=0,"N/A",F10/D10) -> 0.05 | H10: 787500 | I10: =IF($K$5=0,"N/A",E10/$K$5) -> 787500 | J10: =IF(C10=0,"N/A",I10*$K$4) -> 9450000 | K10: =IF($K$4-$K$5<0,0,$K$4-$K$5) -> 7 | L10: =IF(G10="N/A","N/A",IF(ABS(G10)<=0.1,"On Track",IF(ABS(G10)<=0.2,"Watch","Off Track"))) -> On Track
B11: Equipment, Supplies & Commodities | C11: 7500000 | D11: =C11*$K$5/$K$4 -> 3125000 | E11: 3281250 | F11: =E11-D11 -> 156250 | G11: =IF(D11=0,"N/A",F11/D11) -> 0.05 | H11: 656250 | I11: =IF($K$5=0,"N/A",E11/$K$5) -> 656250 | J11: =IF(C11=0,"N/A",I11*$K$4) -> 7875000 | K11: =IF($K$4-$K$5<0,0,$K$4-$K$5) -> 7 | L11: =IF(G11="N/A","N/A",IF(ABS(G11)<=0.1,"On Track",IF(ABS(G11)<=0.2,"Watch","Off Track"))) -> On Track
B12: Training & Capacity Building | C12: 6000000 | D12: =C12*$K$5/$K$4 -> 2500000 | E12: 2625000 | F12: =E12-D12 -> 125000 | G12: =IF(D12=0,"N/A",F12/D12) -> 0.05 | H12: 525000 | I12: =IF($K$5=0,"N/A",E12/$K$5) -> 525000 | J12: =IF(C12=0,"N/A",I12*$K$4) -> 6300000 | K12: =IF($K$4-$K$5<0,0,$K$4-$K$5) -> 7 | L12: =IF(G12="N/A","N/A",IF(ABS(G12)<=0.1,"On Track",IF(ABS(G12)<=0.2,"Watch","Off Track"))) -> On Track
B13: Sub-awards / Partner Disbursements | C13: 9500000 | D13: =C13*$K$5/$K$4 -> 3958333.3 | E13: 4156250 | F13: =E13-D13 -> 197916.67 | G13: =IF(D13=0,"N/A",F13/D13) -> 0.05 | H13: 831250 | I13: =IF($K$5=0,"N/A",E13/$K$5) -> 831250 | J13: =IF(C13=0,"N/A",I13*$K$4) -> 9975000 | K13: =IF($K$4-$K$5<0,0,$K$4-$K$5) -> 7 | L13: =IF(G13="N/A","N/A",IF(ABS(G13)<=0.1,"On Track",IF(ABS(G13)<=0.2,"Watch","Off Track"))) -> On Track
B14: Monitoring, Evaluation & Learning | C14: 4000000 | D14: =C14*$K$5/$K$4 -> 1666666.7 | E14: 1750000 | F14: =E14-D14 -> 83333.333 | G14: =IF(D14=0,"N/A",F14/D14) -> 0.05 | H14: 350000 | I14: =IF($K$5=0,"N/A",E14/$K$5) -> 350000 | J14: =IF(C14=0,"N/A",I14*$K$4) -> 4200000 | K14: =IF($K$4-$K$5<0,0,$K$4-$K$5) -> 7 | L14: =IF(G14="N/A","N/A",IF(ABS(G14)<=0.1,"On Track",IF(ABS(G14)<=0.2,"Watch","Off Track"))) -> On Track
B15: Travel & Transport | C15: 6500000 | D15: =C15*$K$5/$K$4 -> 2708333.3 | E15: 2843750 | F15: =E15-D15 -> 135416.67 | G15: =IF(D15=0,"N/A",F15/D15) -> 0.05 | H15: 568750 | I15: =IF($K$5=0,"N/A",E15/$K$5) -> 568750 | J15: =IF(C15=0,"N/A",I15*$K$4) -> 6825000 | K15: =IF($K$4-$K$5<0,0,$K$4-$K$5) -> 7 | L15: =IF(G15="N/A","N/A",IF(ABS(G15)<=0.1,"On Track",IF(ABS(G15)<=0.2,"Watch","Off Track"))) -> On Track
B16: Administration & Overheads | C16: 3000000 | D16: =C16*$K$5/$K$4 -> 1250000 | E16: 1312500 | F16: =E16-D16 -> 62500 | G16: =IF(D16=0,"N/A",F16/D16) -> 0.05 | H16: 262500 | I16: =IF($K$5=0,"N/A",E16/$K$5) -> 262500 | J16: =IF(C16=0,"N/A",I16*$K$4) -> 3150000 | K16: =IF($K$4-$K$5<0,0,$K$4-$K$5) -> 7 | L16: =IF(G16="N/A","N/A",IF(ABS(G16)<=0.1,"On Track",IF(ABS(G16)<=0.2,"Watch","Off Track"))) -> On Track
B17: Other Direct Costs / Contingency | C17: 5000000 | D17: =C17*$K$5/$K$4 -> 2083333.3 | E17: 2187500 | F17: =E17-D17 -> 104166.67 | G17: =IF(D17=0,"N/A",F17/D17) -> 0.05 | H17: 437500 | I17: =IF($K$5=0,"N/A",E17/$K$5) -> 437500 | J17: =IF(C17=0,"N/A",I17*$K$4) -> 5250000 | K17: =IF($K$4-$K$5<0,0,$K$4-$K$5) -> 7 | L17: =IF(G17="N/A","N/A",IF(ABS(G17)<=0.1,"On Track",IF(ABS(G17)<=0.2,"Watch","Off Track"))) -> On Track
B18: TOTAL PROJECT BUDGET | C18: =SUM(C9:C17) -> 68500000 | D18: =SUM(D9:D17) -> 28541667 | E18: =SUM(E9:E17) -> 29968750 | F18: =E18-D18 -> 1427083.3 | G18: =IF(D18=0,"N/A",F18/D18) -> 0.05 | H18: =SUM(H9:H17) -> 5993750 | I18: =IF($K$5=0,"N/A",E18/$K$5) -> 5993750 | J18: =IF(C18=0,"N/A",I18*$K$4) -> 71925000 | K18: =IF($K$4-$K$5<0,0,$K$4-$K$5) -> 7 | L18: =IF(G18="N/A","N/A",IF(ABS(G18)<=0.1,"On Track",IF(ABS(G18)<=0.2,"Watch","Off Track"))) -> On Track
B19: Planned cumulative budget assumes even (straight-line) spend across the project duration. Variance >20% in either direction triggers Off Track — overspend risks a funding gap; underspend risks an end-of-award absorption/refund issue.
B21: SECTION B · TECHNICAL / DONOR INDICATOR PERFORMANCE
B22: Indicator | C22: Unit / Definition | D22: Annual Target | E22: Planned Cumulative Target to Date | F22: Actual Cumulative Result to Date | G22: Achievement (%) | L22: RAG
B23: Tracer Indicator 1 | C23: Define per donor M&E framework | D23: 1200 | E23: =D23*$K$5/$K$4 -> 500 | F23: 465 | G23: =IF(E23=0,"N/A",F23/E23) -> 0.93 | L23: =IF(G23="N/A","N/A",IF(G23>=0.9,"On Track",IF(G23>=0.75,"Watch","Off Track"))) -> On Track
B24: Tracer Indicator 2 | C24: Define per donor M&E framework | D24: 600 | E24: =D24*$K$5/$K$4 -> 250 | F24: 232 | G24: =IF(E24=0,"N/A",F24/E24) -> 0.928 | L24: =IF(G24="N/A","N/A",IF(G24>=0.9,"On Track",IF(G24>=0.75,"Watch","Off Track"))) -> On Track
B25: Tracer Indicator 3 | C25: Define per donor M&E framework | D25: 900 | E25: =D25*$K$5/$K$4 -> 375 | F25: 349 | G25: =IF(E25=0,"N/A",F25/E25) -> 0.93066667 | L25: =IF(G25="N/A","N/A",IF(G25>=0.9,"On Track",IF(G25>=0.75,"Watch","Off Track"))) -> On Track
B26: Tracer Indicator 4 | C26: Define per donor M&E framework | D26: 450 | E26: =D26*$K$5/$K$4 -> 187.5 | F26: 174 | G26: =IF(E26=0,"N/A",F26/E26) -> 0.928 | L26: =IF(G26="N/A","N/A",IF(G26>=0.9,"On Track",IF(G26>=0.75,"Watch","Off Track"))) -> On Track
B27: Tracer Indicator 5 | C27: Define per donor M&E framework | D27: 1500 | E27: =D27*$K$5/$K$4 -> 625 | F27: 581 | G27: =IF(E27=0,"N/A",F27/E27) -> 0.9296 | L27: =IF(G27="N/A","N/A",IF(G27>=0.9,"On Track",IF(G27>=0.75,"Watch","Off Track"))) -> On Track
B28: Tracer Indicator 6 | C28: Define per donor M&E framework | D28: 300 | E28: =D28*$K$5/$K$4 -> 125 | F28: 116 | G28: =IF(E28=0,"N/A",F28/E28) -> 0.928 | L28: =IF(G28="N/A","N/A",IF(G28>=0.9,"On Track",IF(G28>=0.75,"Watch","Off Track"))) -> On Track
B29: Tracer Indicator 7 | C29: Define per donor M&E framework | D29: 750 | E29: =D29*$K$5/$K$4 -> 312.5 | F29: 291 | G29: =IF(E29=0,"N/A",F29/E29) -> 0.9312 | L29: =IF(G29="N/A","N/A",IF(G29>=0.9,"On Track",IF(G29>=0.75,"Watch","Off Track"))) -> On Track
B30: Tracer Indicator 8 | C30: Define per donor M&E framework | D30: 200 | E30: =D30*$K$5/$K$4 -> 83.333333 | F30: 78 | G30: =IF(E30=0,"N/A",F30/E30) -> 0.936 | L30: =IF(G30="N/A","N/A",IF(G30>=0.9,"On Track",IF(G30>=0.75,"Watch","Off Track"))) -> On Track
B31: Indicator names are standard/illustrative donor indicators for this project type — replace with your specific donor's exact indicator list, definitions and reporting frequency where they differ.
B33: SECTION C · OVERALL PROJECT HEALTH
B34: Financial RAG (Total Budget): | E34: =L18 -> On Track | F34: Off-Track Budget Lines: | J34: =COUNTIF(L9:L17,"Off Track")&" of "&COUNTA(L9:L17) -> 0 of 9
B35: Technical RAG (Indicator Performance): | E35: =IF(COUNTIF(L23:L30,"Off Track")>0,"Off Track",IF(COUNTIF(L23:L30,"Watch")>0,"Watch","On Track")) -> On Track | F35: Off-Track Indicators: | J35: =COUNTIF(L23:L30,"Off Track")&" of "&COUNTA(L23:L30) -> 0 of 8
B36: OVERALL PROJECT HEALTH: | E36: =IF(OR(E34="Off Track",E35="Off Track"),"Off Track",IF(OR(E34="Watch",E35="Watch"),"Watch","On Track")) -> On Track
B38: Programme Manager's Narrative — key achievements, bottlenecks, and corrective actions this month:
B39: Type narrative here...

Sheet PEP
B2: Partnership for Education of Health Professionals (PEP) Monthly Performance Monitoring
B4: Donor: | C4: Novo Nordisk Foundation (NNF) | E4: Reporting Month: | G4: =TODAY() -> 46202 | I4: Project Duration (months): | K4: 18
B5: Project Code: | C5: CHAK/2026/07 | E5: Reporting Period: | G5: Type reporting period here... | I5: Months Elapsed to Date: | K5: 4
B7: SECTION A · FINANCIAL PERFORMANCE — BURN RATE & BUDGET VS. ACTUAL (BVA)
B8: Budget Line | C8: Annual Budget | D8: Planned Cumulative Budget to Date | E8: Actual Cumulative Expenditure to Date | F8: Variance ($) | G8: Variance (%) | H8: Current Month Expenditure | I8: Avg. Monthly Burn Rate | J8: Projected Annual Expenditure | K8: Months Remaining | L8: RAG
B9: Personnel & HR | C9: 18000000 | D9: =C9*$K$5/$K$4 -> 4000000 | E9: 3120000 | F9: =E9-D9 -> -880000 | G9: =IF(D9=0,"N/A",F9/D9) -> -0.22 | H9: 780000 | I9: =IF($K$5=0,"N/A",E9/$K$5) -> 780000 | J9: =IF(C9=0,"N/A",I9*$K$4) -> 14040000 | K9: =IF($K$4-$K$5<0,0,$K$4-$K$5) -> 14 | L9: =IF(G9="N/A","N/A",IF(ABS(G9)<=0.1,"On Track",IF(ABS(G9)<=0.2,"Watch","Off Track"))) -> Off Track
B10: Technical / Program Activities | C10: 9000000 | D10: =C10*$K$5/$K$4 -> 2000000 | E10: 1560000 | F10: =E10-D10 -> -440000 | G10: =IF(D10=0,"N/A",F10/D10) -> -0.22 | H10: 390000 | I10: =IF($K$5=0,"N/A",E10/$K$5) -> 390000 | J10: =IF(C10=0,"N/A",I10*$K$4) -> 7020000 | K10: =IF($K$4-$K$5<0,0,$K$4-$K$5) -> 14 | L10: =IF(G10="N/A","N/A",IF(ABS(G10)<=0.1,"On Track",IF(ABS(G10)<=0.2,"Watch","Off Track"))) -> Off Track
B11: Equipment, Supplies & Commodities | C11: 7500000 | D11: =C11*$K$5/$K$4 -> 1666666.7 | E11: 1300000 | F11: =E11-D11 -> -366666.67 | G11: =IF(D11=0,"N/A",F11/D11) -> -0.22 | H11: 325000 | I11: =IF($K$5=0,"N/A",E11/$K$5) -> 325000 | J11: =IF(C11=0,"N/A",I11*$K$4) -> 5850000 | K11: =IF($K$4-$K$5<0,0,$K$4-$K$5) -> 14 | L11: =IF(G11="N/A","N/A",IF(ABS(G11)<=0.1,"On Track",IF(ABS(G11)<=0.2,"Watch","Off Track"))) -> Off Track
B12: Training & Capacity Building | C12: 6000000 | D12: =C12*$K$5/$K$4 -> 1333333.3 | E12: 1040000 | F12: =E12-D12 -> -293333.33 | G12: =IF(D12=0,"N/A",F12/D12) -> -0.22 | H12: 260000 | I12: =IF($K$5=0,"N/A",E12/$K$5) -> 260000 | J12: =IF(C12=0,"N/A",I12*$K$4) -> 4680000 | K12: =IF($K$4-$K$5<0,0,$K$4-$K$5) -> 14 | L12: =IF(G12="N/A","N/A",IF(ABS(G12)<=0.1,"On Track",IF(ABS(G12)<=0.2,"Watch","Off Track"))) -> Off Track
B13: Sub-awards / Partner Disbursements | C13: 9500000 | D13: =C13*$K$5/$K$4 -> 2111111.1 | E13: 1646667 | F13: =E13-D13 -> -464444.11 | G13: =IF(D13=0,"N/A",F13/D13) -> -0.21999984 | H13: 411667 | I13: =IF($K$5=0,"N/A",E13/$K$5) -> 411666.75 | J13: =IF(C13=0,"N/A",I13*$K$4) -> 7410001.5 | K13: =IF($K$4-$K$5<0,0,$K$4-$K$5) -> 14 | L13: =IF(G13="N/A","N/A",IF(ABS(G13)<=0.1,"On Track",IF(ABS(G13)<=0.2,"Watch","Off Track"))) -> Off Track
B14: Monitoring, Evaluation & Learning | C14: 4000000 | D14: =C14*$K$5/$K$4 -> 888888.89 | E14: 693333 | F14: =E14-D14 -> -195555.89 | G14: =IF(D14=0,"N/A",F14/D14) -> -0.22000037 | H14: 173333 | I14: =IF($K$5=0,"N/A",E14/$K$5) -> 173333.25 | J14: =IF(C14=0,"N/A",I14*$K$4) -> 3119998.5 | K14: =IF($K$4-$K$5<0,0,$K$4-$K$5) -> 14 | L14: =IF(G14="N/A","N/A",IF(ABS(G14)<=0.1,"On Track",IF(ABS(G14)<=0.2,"Watch","Off Track"))) -> Off Track
