Workbook
Name SpotFolder: 'Live Data'!$C$5

Sheet Cluster Summary
B1: Digital Health Systems & Electronic Reporting Coverage, Data Systems
B2: Reporting period | D2: 46266
B3: Upload month counted (YYYY-MM) | D3: 2026-10
B5: Expected Sites | D5: C&T | F5: HTS | H5: MNCH | J5: PrEP | L5: Overall | N5: FAA M22 tier
B6: =C31 -> 208 | D6: =E31 -> 1 | F6: =H31 -> 0.92788462 | H6: =K31 -> 0.86057692 | J6: =N31 -> 0.78846154 | L6: =P31 -> 0.89423077 | N6: ='FAA Milestone Link'!C40 -> 1
N8: ="("&'FAA Milestone Link'!C28&" rate "&TEXT('FAA Milestone Link'!C38,"0.0%")&")" -> (C&T rate 100.0%)
B9: Cluster / County | C9: Expected Sites (C&T) | D9: Care & Treatment | G9: HTS | J9: MNCH | M9: PrEP | P9: Overall % (all 4 dockets)
D10: Uploaded | E10: % Uploaded | F10: Pending | G10: Uploaded | H10: % Uploaded | I10: Pending | J10: Uploaded | K10: % Uploaded | L10: Pending | M10: Uploaded | N10: % Uploaded | O10: Pending
B11: Cluster 1 | C11: =C12+C13 -> 65 | D11: =D12+D13 -> 65 | E11: =IF(C11=0,0,D11/C11) -> 1 | F11: =MAX(C11-D11,0) -> 0 | G11: =G12+G13 -> 57 | H11: =IF(C11=0,0,G11/C11) -> 0.87692308 | I11: =MAX(C11-G11,0) -> 8 | J11: =J12+J13 -> 55 | K11: =IF(C11=0,0,J11/C11) -> 0.84615385 | L11: =MAX(C11-J11,0) -> 10 | M11: =M12+M13 -> 38 | N11: =IF(C11=0,0,M11/C11) -> 0.58461538 | O11: =MAX(C11-M11,0) -> 27 | P11: =IF(C11=0,0,(D11+G11+J11+M11)/(C11*4)) -> 0.82692308
B12: Meru | C12: =SUMIFS(Data!$P$2:$P$2500,Data!$N$2:$N$2500,"Cluster 1",Data!$M$2:$M$2500,"MERU") -> 64 | D12: =SUMIFS(Data!$O$2:$O$2500,Data!$F$2:$F$2500,"C&T",Data!$N$2:$N$2500,"Cluster 1",Data!$M$2:$M$2500,"MERU",Data!$L$2:$L$2500,$D$3) -> 64 | E12: =IF(C12=0,0,D12/C12) -> 1 | F12: =MAX(C12-D12,0) -> 0 | G12: =SUMIFS(Data!$O$2:$O$2500,Data!$F$2:$F$2500,"HTS",Data!$N$2:$N$2500,"Cluster 1",Data!$M$2:$M$2500,"MERU",Data!$L$2:$L$2500,$D$3) -> 56 | H12: =IF(C12=0,0,G12/C12) -> 0.875 | I12: =MAX(C12-G12,0) -> 8 | J12: =SUMIFS(Data!$O$2:$O$2500,Data!$F$2:$F$2500,"MNCH",Data!$N$2:$N$2500,"Cluster 1",Data!$M$2:$M$2500,"MERU",Data!$L$2:$L$2500,$D$3) -> 54 | K12: =IF(C12=0,0,J12/C12) -> 0.84375 | L12: =MAX(C12-J12,0) -> 10 | M12: =SUMIFS(Data!$O$2:$O$2500,Data!$F$2:$F$2500,"PREP",Data!$N$2:$N$2500,"Cluster 1",Data!$M$2:$M$2500,"MERU",Data!$L$2:$L$2500,$D$3) -> 37 | N12: =IF(C12=0,0,M12/C12) -> 0.578125 | O12: =MAX(C12-M12,0) -> 27 | P12: =IF(C12=0,0,(D12+G12+J12+M12)/(C12*4)) -> 0.82421875
B13: Laikipia | C13: =SUMIFS(Data!$P$2:$P$2500,Data!$N$2:$N$2500,"Cluster 1",Data!$M$2:$M$2500,"LAIKIPIA") -> 1 | D13: =SUMIFS(Data!$O$2:$O$2500,Data!$F$2:$F$2500,"C&T",Data!$N$2:$N$2500,"Cluster 1",Data!$M$2:$M$2500,"LAIKIPIA",Data!$L$2:$L$2500,$D$3) -> 1 | E13: =IF(C13=0,0,D13/C13) -> 1 | F13: =MAX(C13-D13,0) -> 0 | G13: =SUMIFS(Data!$O$2:$O$2500,Data!$F$2:$F$2500,"HTS",Data!$N$2:$N$2500,"Cluster 1",Data!$M$2:$M$2500,"LAIKIPIA",Data!$L$2:$L$2500,$D$3) -> 1 | H13: =IF(C13=0,0,G13/C13) -> 1 | I13: =MAX(C13-G13,0) -> 0 | J13: =SUMIFS(Data!$O$2:$O$2500,Data!$F$2:$F$2500,"MNCH",Data!$N$2:$N$2500,"Cluster 1",Data!$M$2:$M$2500,"LAIKIPIA",Data!$L$2:$L$2500,$D$3) -> 1 | K13: =IF(C13=0,0,J13/C13) -> 1 | L13: =MAX(C13-J13,0) -> 0 | M13: =SUMIFS(Data!$O$2:$O$2500,Data!$F$2:$F$2500,"PREP",Data!$N$2:$N$2500,"Cluster 1",Data!$M$2:$M$2500,"LAIKIPIA",Data!$L$2:$L$2500,$D$3) -> 1 | N13: =IF(C13=0,0,M13/C13) -> 1 | O13: =MAX(C13-M13,0) -> 0 | P13: =IF(C13=0,0,(D13+G13+J13+M13)/(C13*4)) -> 1
B14: Cluster 2 | C14: =C15+C16+C17+C18 -> 64 | D14: =D15+D16+D17+D18 -> 64 | E14: =IF(C14=0,0,D14/C14) -> 1 | F14: =MAX(C14-D14,0) -> 0 | G14: =G15+G16+G17+G18 -> 60 | H14: =IF(C14=0,0,G14/C14) -> 0.9375 | I14: =MAX(C14-G14,0) -> 4 | J14: =J15+J16+J17+J18 -> 53 | K14: =IF(C14=0,0,J14/C14) -> 0.828125 | L14: =MAX(C14-J14,0) -> 11 | M14: =M15+M16+M17+M18 -> 51 | N14: =IF(C14=0,0,M14/C14) -> 0.796875 | O14: =MAX(C14-M14,0) -> 13 | P14: =IF(C14=0,0,(D14+G14+J14+M14)/(C14*4)) -> 0.890625
B15: Embu | C15: =SUMIFS(Data!$P$2:$P$2500,Data!$N$2:$N$2500,"Cluster 2",Data!$M$2:$M$2500,"EMBU") -> 35 | D15: =SUMIFS(Data!$O$2:$O$2500,Data!$F$2:$F$2500,"C&T",Data!$N$2:$N$2500,"Cluster 2",Data!$M$2:$M$2500,"EMBU",Data!$L$2:$L$2500,$D$3) -> 35 | E15: =IF(C15=0,0,D15/C15) -> 1 | F15: =MAX(C15-D15,0) -> 0 | G15: =SUMIFS(Data!$O$2:$O$2500,Data!$F$2:$F$2500,"HTS",Data!$N$2:$N$2500,"Cluster 2",Data!$M$2:$M$2500,"EMBU",Data!$L$2:$L$2500,$D$3) -> 32 | H15: =IF(C15=0,0,G15/C15) -> 0.91428571 | I15: =MAX(C15-G15,0) -> 3 | J15: =SUMIFS(Data!$O$2:$O$2500,Data!$F$2:$F$2500,"MNCH",Data!$N$2:$N$2500,"Cluster 2",Data!$M$2:$M$2500,"EMBU",Data!$L$2:$L$2500,$D$3) -> 26 | K15: =IF(C15=0,0,J15/C15) -> 0.74285714 | L15: =MAX(C15-J15,0) -> 9 | M15: =SUMIFS(Data!$O$2:$O$2500,Data!$F$2:$F$2500,"PREP",Data!$N$2:$N$2500,"Cluster 2",Data!$M$2:$M$2500,"EMBU",Data!$L$2:$L$2500,$D$3) -> 26 | N15: =IF(C15=0,0,M15/C15) -> 0.74285714 | O15: =MAX(C15-M15,0) -> 9 | P15: =IF(C15=0,0,(D15+G15+J15+M15)/(C15*4)) -> 0.85
B16: Tharaka-Nithi | C16: =SUMIFS(Data!$P$2:$P$2500,Data!$N$2:$N$2500,"Cluster 2",Data!$M$2:$M$2500,"THARAKA-NITHI") -> 23 | D16: =SUMIFS(Data!$O$2:$O$2500,Data!$F$2:$F$2500,"C&T",Data!$N$2:$N$2500,"Cluster 2",Data!$M$2:$M$2500,"THARAKA-NITHI",Data!$L$2:$L$2500,$D$3) -> 23 | E16: =IF(C16=0,0,D16/C16) -> 1 | F16: =MAX(C16-D16,0) -> 0 | G16: =SUMIFS(Data!$O$2:$O$2500,Data!$F$2:$F$2500,"HTS",Data!$N$2:$N$2500,"Cluster 2",Data!$M$2:$M$2500,"THARAKA-NITHI",Data!$L$2:$L$2500,$D$3) -> 22 | H16: =IF(C16=0,0,G16/C16) -> 0.95652174 | I16: =MAX(C16-G16,0) -> 1 | J16: =SUMIFS(Data!$O$2:$O$2500,Data!$F$2:$F$2500,"MNCH",Data!$N$2:$N$2500,"Cluster 2",Data!$M$2:$M$2500,"THARAKA-NITHI",Data!$L$2:$L$2500,$D$3) -> 21 | K16: =IF(C16=0,0,J16/C16) -> 0.91304348 | L16: =MAX(C16-J16,0) -> 2 | M16: =SUMIFS(Data!$O$2:$O$2500,Data!$F$2:$F$2500,"PREP",Data!$N$2:$N$2500,"Cluster 2",Data!$M$2:$M$2500,"THARAKA-NITHI",Data!$L$2:$L$2500,$D$3) -> 19 | N16: =IF(C16=0,0,M16/C16) -> 0.82608696 | O16: =MAX(C16-M16,0) -> 4 | P16: =IF(C16=0,0,(D16+G16+J16+M16)/(C16*4)) -> 0.92391304
B17: Kirinyaga | C17: =SUMIFS(Data!$P$2:$P$2500,Data!$N$2:$N$2500,"Cluster 2",Data!$M$2:$M$2500,"KIRINYAGA") -> 4 | D17: =SUMIFS(Data!$O$2:$O$2500,Data!$F$2:$F$2500,"C&T",Data!$N$2:$N$2500,"Cluster 2",Data!$M$2:$M$2500,"KIRINYAGA",Data!$L$2:$L$2500,$D$3) -> 4 | E17: =IF(C17=0,0,D17/C17) -> 1 | F17: =MAX(C17-D17,0) -> 0 | G17: =SUMIFS(Data!$O$2:$O$2500,Data!$F$2:$F$2500,"HTS",Data!$N$2:$N$2500,"Cluster 2",Data!$M$2:$M$2500,"KIRINYAGA",Data!$L$2:$L$2500,$D$3) -> 4 | H17: =IF(C17=0,0,G17/C17) -> 1 | I17: =MAX(C17-G17,0) -> 0 | J17: =SUMIFS(Data!$O$2:$O$2500,Data!$F$2:$F$2500,"MNCH",Data!$N$2:$N$2500,"Cluster 2",Data!$M$2:$M$2500,"KIRINYAGA",Data!$L$2:$L$2500,$D$3) -> 4 | K17: =IF(C17=0,0,J17/C17) -> 1 | L17: =MAX(C17-J17,0) -> 0 | M17: =SUMIFS(Data!$O$2:$O$2500,Data!$F$2:$F$2500,"PREP",Data!$N$2:$N$2500,"Cluster 2",Data!$M$2:$M$2500,"KIRINYAGA",Data!$L$2:$L$2500,$D$3) -> 4 | N17: =IF(C17=0,0,M17/C17) -> 1 | O17: =MAX(C17-M17,0) -> 0 | P17: =IF(C17=0,0,(D17+G17+J17+M17)/(C17*4)) -> 1
B18: Nyeri | C18: =SUMIFS(Data!$P$2:$P$2500,Data!$N$2:$N$2500,"Cluster 2",Data!$M$2:$M$2500,"NYERI") -> 2 | D18: =SUMIFS(Data!$O$2:$O$2500,Data!$F$2:$F$2500,"C&T",Data!$N$2:$N$2500,"Cluster 2",Data!$M$2:$M$2500,"NYERI",Data!$L$2:$L$2500,$D$3) -> 2 | E18: =IF(C18=0,0,D18/C18) -> 1 | F18: =MAX(C18-D18,0) -> 0 | G18: =SUMIFS(Data!$O$2:$O$2500,Data!$F$2:$F$2500,"HTS",Data!$N$2:$N$2500,"Cluster 2",Data!$M$2:$M$2500,"NYERI",Data!$L$2:$L$2500,$D$3) -> 2 | H18: =IF(C18=0,0,G18/C18) -> 1 | I18: =MAX(C18-G18,0) -> 0 | J18: =SUMIFS(Data!$O$2:$O$2500,Data!$F$2:$F$2500,"MNCH",Data!$N$2:$N$2500,"Cluster 2",Data!$M$2:$M$2500,"NYERI",Data!$L$2:$L$2500,$D$3) -> 2 | K18: =IF(C18=0,0,J18/C18) -> 1 | L18: =MAX(C18-J18,0) -> 0 | M18: =SUMIFS(Data!$O$2:$O$2500,Data!$F$2:$F$2500,"PREP",Data!$N$2:$N$2500,"Cluster 2",Data!$M$2:$M$2500,"NYERI",Data!$L$2:$L$2500,$D$3) -> 2 | N18: =IF(C18=0,0,M18/C18) -> 1 | O18: =MAX(C18-M18,0) -> 0 | P18: =IF(C18=0,0,(D18+G18+J18+M18)/(C18*4)) -> 1
B19: Cluster 3 | C19: =C20+C21+C22 -> 13 | D19: =D20+D21+D22 -> 13 | E19: =IF(C19=0,0,D19/C19) -> 1 | F19: =MAX(C19-D19,0) -> 0 | G19: =G20+G21+G22 -> 13 | H19: =IF(C19=0,0,G19/C19) -> 1 | I19: =MAX(C19-G19,0) -> 0 | J19: =J20+J21+J22 -> 12 | K19: =IF(C19=0,0,J19/C19) -> 0.92307692 | L19: =MAX(C19-J19,0) -> 1 | M19: =M20+M21+M22 -> 13 | N19: =IF(C19=0,0,M19/C19) -> 1 | O19: =MAX(C19-M19,0) -> 0 | P19: =IF(C19=0,0,(D19+G19+J19+M19)/(C19*4)) -> 0.98076923
B20: Kiambu | C20: =SUMIFS(Data!$P$2:$P$2500,Data!$N$2:$N$2500,"Cluster 3",Data!$M$2:$M$2500,"KIAMBU") -> 11 | D20: =SUMIFS(Data!$O$2:$O$2500,Data!$F$2:$F$2500,"C&T",Data!$N$2:$N$2500,"Cluster 3",Data!$M$2:$M$2500,"KIAMBU",Data!$L$2:$L$2500,$D$3) -> 11 | E20: =IF(C20=0,0,D20/C20) -> 1 | F20: =MAX(C20-D20,0) -> 0 | G20: =SUMIFS(Data!$O$2:$O$2500,Data!$F$2:$F$2500,"HTS",Data!$N$2:$N$2500,"Cluster 3",Data!$M$2:$M$2500,"KIAMBU",Data!$L$2:$L$2500,$D$3) -> 11 | H20: =IF(C20=0,0,G20/C20) -> 1 | I20: =MAX(C20-G20,0) -> 0 | J20: =SUMIFS(Data!$O$2:$O$2500,Data!$F$2:$F$2500,"MNCH",Data!$N$2:$N$2500,"Cluster 3",Data!$M$2:$M$2500,"KIAMBU",Data!$L$2:$L$2500,$D$3) -> 10 | K20: =IF(C20=0,0,J20/C20) -> 0.90909091 | L20: =MAX(C20-J20,0) -> 1 | M20: =SUMIFS(Data!$O$2:$O$2500,Data!$F$2:$F$2500,"PREP",Data!$N$2:$N$2500,"Cluster 3",Data!$M$2:$M$2500,"KIAMBU",Data!$L$2:$L$2500,$D$3) -> 11 | N20: =IF(C20=0,0,M20/C20) -> 1 | O20: =MAX(C20-M20,0) -> 0 | P20: =IF(C20=0,0,(D20+G20+J20+M20)/(C20*4)) -> 0.97727273
B21: Murang'a | C21: =SUMIFS(Data!$P$2:$P$2500,Data!$N$2:$N$2500,"Cluster 3",Data!$M$2:$M$2500,"MURANG'A") -> 1 | D21: =SUMIFS(Data!$O$2:$O$2500,Data!$F$2:$F$2500,"C&T",Data!$N$2:$N$2500,"Cluster 3",Data!$M$2:$M$2500,"MURANG'A",Data!$L$2:$L$2500,$D$3) -> 1 | E21: =IF(C21=0,0,D21/C21) -> 1 | F21: =MAX(C21-D21,0) -> 0 | G21: =SUMIFS(Data!$O$2:$O$2500,Data!$F$2:$F$2500,"HTS",Data!$N$2:$N$2500,"Cluster 3",Data!$M$2:$M$2500,"MURANG'A",Data!$L$2:$L$2500,$D$3) -> 1 | H21: =IF(C21=0,0,G21/C21) -> 1 | I21: =MAX(C21-G21,0) -> 0 | J21: =SUMIFS(Data!$O$2:$O$2500,Data!$F$2:$F$2500,"MNCH",Data!$N$2:$N$2500,"Cluster 3",Data!$M$2:$M$2500,"MURANG'A",Data!$L$2:$L$2500,$D$3) -> 1 | K21: =IF(C21=0,0,J21/C21) -> 1 | L21: =MAX(C21-J21,0) -> 0 | M21: =SUMIFS(Data!$O$2:$O$2500,Data!$F$2:$F$2500,"PREP",Data!$N$2:$N$2500,"Cluster 3",Data!$M$2:$M$2500,"MURANG'A",Data!$L$2:$L$2500,$D$3) -> 1 | N21: =IF(C21=0,0,M21/C21) -> 1 | O21: =MAX(C21-M21,0) -> 0 | P21: =IF(C21=0,0,(D21+G21+J21+M21)/(C21*4)) -> 1
B22: Kajiado | C22: =SUMIFS(Data!$P$2:$P$2500,Data!$N$2:$N$2500,"Cluster 3",Data!$M$2:$M$2500,"KAJIADO") -> 1 | D22: =SUMIFS(Data!$O$2:$O$2500,Data!$F$2:$F$2500,"C&T",Data!$N$2:$N$2500,"Cluster 3",Data!$M$2:$M$2500,"KAJIADO",Data!$L$2:$L$2500,$D$3) -> 1 | E22: =IF(C22=0,0,D22/C22) -> 1 | F22: =MAX(C22-D22,0) -> 0 | G22: =SUMIFS(Data!$O$2:$O$2500,Data!$F$2:$F$2500,"HTS",Data!$N$2:$N$2500,"Cluster 3",Data!$M$2:$M$2500,"KAJIADO",Data!$L$2:$L$2500,$D$3) -> 1 | H22: =IF(C22=0,0,G22/C22) -> 1 | I22: =MAX(C22-G22,0) -> 0 | J22: =SUMIFS(Data!$O$2:$O$2500,Data!$F$2:$F$2500,"MNCH",Data!$N$2:$N$2500,"Cluster 3",Data!$M$2:$M$2500,"KAJIADO",Data!$L$2:$L$2500,$D$3) -> 1 | K22: =IF(C22=0,0,J22/C22) -> 1 | L22: =MAX(C22-J22,0) -> 0 | M22: =SUMIFS(Data!$O$2:$O$2500,Data!$F$2:$F$2500,"PREP",Data!$N$2:$N$2500,"Cluster 3",Data!$M$2:$M$2500,"KAJIADO",Data!$L$2:$L$2500,$D$3) -> 1 | N22: =IF(C22=0,0,M22/C22) -> 1 | O22: =MAX(C22-M22,0) -> 0 | P22: =IF(C22=0,0,(D22+G22+J22+M22)/(C22*4)) -> 1
B23: Cluster 4 | C23: =C24+C25+C26 -> 42 | D23: =D24+D25+D26 -> 42 | E23: =IF(C23=0,0,D23/C23) -> 1 | F23: =MAX(C23-D23,0) -> 0 | G23: =G24+G25+G26 -> 39 | H23: =IF(C23=0,0,G23/C23) -> 0.92857143 | I23: =MAX(C23-G23,0) -> 3 | J23: =J24+J25+J26 -> 39 | K23: =IF(C23=0,0,J23/C23) -> 0.92857143 | L23: =MAX(C23-J23,0) -> 3 | M23: =M24+M25+M26 -> 39 | N23: =IF(C23=0,0,M23/C23) -> 0.92857143 | O23: =MAX(C23-M23,0) -> 3 | P23: =IF(C23=0,0,(D23+G23+J23+M23)/(C23*4)) -> 0.94642857
B24: Nyandarua | C24: =SUMIFS(Data!$P$2:$P$2500,Data!$N$2:$N$2500,"Cluster 4",Data!$M$2:$M$2500,"NYANDARUA") -> 36 | D24: =SUMIFS(Data!$O$2:$O$2500,Data!$F$2:$F$2500,"C&T",Data!$N$2:$N$2500,"Cluster 4",Data!$M$2:$M$2500,"NYANDARUA",Data!$L$2:$L$2500,$D$3) -> 36 | E24: =IF(C24=0,0,D24/C24) -> 1 | F24: =MAX(C24-D24,0) -> 0 | G24: =SUMIFS(Data!$O$2:$O$2500,Data!$F$2:$F$2500,"HTS",Data!$N$2:$N$2500,"Cluster 4",Data!$M$2:$M$2500,"NYANDARUA",Data!$L$2:$L$2500,$D$3) -> 33 | H24: =IF(C24=0,0,G24/C24) -> 0.91666667 | I24: =MAX(C24-G24,0) -> 3 | J24: =SUMIFS(Data!$O$2:$O$2500,Data!$F$2:$F$2500,"MNCH",Data!$N$2:$N$2500,"Cluster 4",Data!$M$2:$M$2500,"NYANDARUA",Data!$L$2:$L$2500,$D$3) -> 34 | K24: =IF(C24=0,0,J24/C24) -> 0.94444444 | L24: =MAX(C24-J24,0) -> 2 | M24: =SUMIFS(Data!$O$2:$O$2500,Data!$F$2:$F$2500,"PREP",Data!$N$2:$N$2500,"Cluster 4",Data!$M$2:$M$2500,"NYANDARUA",Data!$L$2:$L$2500,$D$3) -> 33 | N24: =IF(C24=0,0,M24/C24) -> 0.91666667 | O24: =MAX(C24-M24,0) -> 3 | P24: =IF(C24=0,0,(D24+G24+J24+M24)/(C24*4)) -> 0.94444444
B25: Narok | C25: =SUMIFS(Data!$P$2:$P$2500,Data!$N$2:$N$2500,"Cluster 4",Data!$M$2:$M$2500,"NAROK") -> 5 | D25: =SUMIFS(Data!$O$2:$O$2500,Data!$F$2:$F$2500,"C&T",Data!$N$2:$N$2500,"Cluster 4",Data!$M$2:$M$2500,"NAROK",Data!$L$2:$L$2500,$D$3) -> 5 | E25: =IF(C25=0,0,D25/C25) -> 1 | F25: =MAX(C25-D25,0) -> 0 | G25: =SUMIFS(Data!$O$2:$O$2500,Data!$F$2:$F$2500,"HTS",Data!$N$2:$N$2500,"Cluster 4",Data!$M$2:$M$2500,"NAROK",Data!$L$2:$L$2500,$D$3) -> 5 | H25: =IF(C25=0,0,G25/C25) -> 1 | I25: =MAX(C25-G25,0) -> 0 | J25: =SUMIFS(Data!$O$2:$O$2500,Data!$F$2:$F$2500,"MNCH",Data!$N$2:$N$2500,"Cluster 4",Data!$M$2:$M$2500,"NAROK",Data!$L$2:$L$2500,$D$3) -> 4 | K25: =IF(C25=0,0,J25/C25) -> 0.8 | L25: =MAX(C25-J25,0) -> 1 | M25: =SUMIFS(Data!$O$2:$O$2500,Data!$F$2:$F$2500,"PREP",Data!$N$2:$N$2500,"Cluster 4",Data!$M$2:$M$2500,"NAROK",Data!$L$2:$L$2500,$D$3) -> 5 | N25: =IF(C25=0,0,M25/C25) -> 1 | O25: =MAX(C25-M25,0) -> 0 | P25: =IF(C25=0,0,(D25+G25+J25+M25)/(C25*4)) -> 0.95
B26: Nakuru | C26: =SUMIFS(Data!$P$2:$P$2500,Data!$N$2:$N$2500,"Cluster 4",Data!$M$2:$M$2500,"NAKURU") -> 1 | D26: =SUMIFS(Data!$O$2:$O$2500,Data!$F$2:$F$2500,"C&T",Data!$N$2:$N$2500,"Cluster 4",Data!$M$2:$M$2500,"NAKURU",Data!$L$2:$L$2500,$D$3) -> 1 | E26: =IF(C26=0,0,D26/C26) -> 1 | F26: =MAX(C26-D26,0) -> 0 | G26: =SUMIFS(Data!$O$2:$O$2500,Data!$F$2:$F$2500,"HTS",Data!$N$2:$N$2500,"Cluster 4",Data!$M$2:$M$2500,"NAKURU",Data!$L$2:$L$2500,$D$3) -> 1 | H26: =IF(C26=0,0,G26/C26) -> 1 | I26: =MAX(C26-G26,0) -> 0 | J26: =SUMIFS(Data!$O$2:$O$2500,Data!$F$2:$F$2500,"MNCH",Data!$N$2:$N$2500,"Cluster 4",Data!$M$2:$M$2500,"NAKURU",Data!$L$2:$L$2500,$D$3) -> 1 | K26: =IF(C26=0,0,J26/C26) -> 1 | L26: =MAX(C26-J26,0) -> 0 | M26: =SUMIFS(Data!$O$2:$O$2500,Data!$F$2:$F$2500,"PREP",Data!$N$2:$N$2500,"Cluster 4",Data!$M$2:$M$2500,"NAKURU",Data!$L$2:$L$2500,$D$3) -> 1 | N26: =IF(C26=0,0,M26/C26) -> 1 | O26: =MAX(C26-M26,0) -> 0 | P26: =IF(C26=0,0,(D26+G26+J26+M26)/(C26*4)) -> 1
B27: Cluster 5 | C27: =C28+C29+C30 -> 24 | D27: =D28+D29+D30 -> 24 | E27: =IF(C27=0,0,D27/C27) -> 1 | F27: =MAX(C27-D27,0) -> 0 | G27: =G28+G29+G30 -> 24 | H27: =IF(C27=0,0,G27/C27) -> 1 | I27: =MAX(C27-G27,0) -> 0 | J27: =J28+J29+J30 -> 20 | K27: =IF(C27=0,0,J27/C27) -> 0.83333333 | L27: =MAX(C27-J27,0) -> 4 | M27: =M28+M29+M30 -> 23 | N27: =IF(C27=0,0,M27/C27) -> 0.95833333 | O27: =MAX(C27-M27,0) -> 1 | P27: =IF(C27=0,0,(D27+G27+J27+M27)/(C27*4)) -> 0.94791667
B28: Kitui | C28: =SUMIFS(Data!$P$2:$P$2500,Data!$N$2:$N$2500,"Cluster 5",Data!$M$2:$M$2500,"KITUI") -> 14 | D28: =SUMIFS(Data!$O$2:$O$2500,Data!$F$2:$F$2500,"C&T",Data!$N$2:$N$2500,"Cluster 5",Data!$M$2:$M$2500,"KITUI",Data!$L$2:$L$2500,$D$3) -> 14 | E28: =IF(C28=0,0,D28/C28) -> 1 | F28: =MAX(C28-D28,0) -> 0 | G28: =SUMIFS(Data!$O$2:$O$2500,Data!$F$2:$F$2500,"HTS",Data!$N$2:$N$2500,"Cluster 5",Data!$M$2:$M$2500,"KITUI",Data!$L$2:$L$2500,$D$3) -> 14 | H28: =IF(C28=0,0,G28/C28) -> 1 | I28: =MAX(C28-G28,0) -> 0 | J28: =SUMIFS(Data!$O$2:$O$2500,Data!$F$2:$F$2500,"MNCH",Data!$N$2:$N$2500,"Cluster 5",Data!$M$2:$M$2500,"KITUI",Data!$L$2:$L$2500,$D$3) -> 11 | K28: =IF(C28=0,0,J28/C28) -> 0.78571429 | L28: =MAX(C28-J28,0) -> 3 | M28: =SUMIFS(Data!$O$2:$O$2500,Data!$F$2:$F$2500,"PREP",Data!$N$2:$N$2500,"Cluster 5",Data!$M$2:$M$2500,"KITUI",Data!$L$2:$L$2500,$D$3) -> 13 | N28: =IF(C28=0,0,M28/C28) -> 0.92857143 | O28: =MAX(C28-M28,0) -> 1 | P28: =IF(C28=0,0,(D28+G28+J28+M28)/(C28*4)) -> 0.92857143
B29: Makueni | C29: =SUMIFS(Data!$P$2:$P$2500,Data!$N$2:$N$2500,"Cluster 5",Data!$M$2:$M$2500,"MAKUENI") -> 6 | D29: =SUMIFS(Data!$O$2:$O$2500,Data!$F$2:$F$2500,"C&T",Data!$N$2:$N$2500,"Cluster 5",Data!$M$2:$M$2500,"MAKUENI",Data!$L$2:$L$2500,$D$3) -> 6 | E29: =IF(C29=0,0,D29/C29) -> 1 | F29: =MAX(C29-D29,0) -> 0 | G29: =SUMIFS(Data!$O$2:$O$2500,Data!$F$2:$F$2500,"HTS",Data!$N$2:$N$2500,"Cluster 5",Data!$M$2:$M$2500,"MAKUENI",Data!$L$2:$L$2500,$D$3) -> 6 | H29: =IF(C29=0,0,G29/C29) -> 1 | I29: =MAX(C29-G29,0) -> 0 | J29: =SUMIFS(Data!$O$2:$O$2500,Data!$F$2:$F$2500,"MNCH",Data!$N$2:$N$2500,"Cluster 5",Data!$M$2:$M$2500,"MAKUENI",Data!$L$2:$L$2500,$D$3) -> 5 | K29: =IF(C29=0,0,J29/C29) -> 0.83333333 | L29: =MAX(C29-J29,0) -> 1 | M29: =SUMIFS(Data!$O$2:$O$2500,Data!$F$2:$F$2500,"PREP",Data!$N$2:$N$2500,"Cluster 5",Data!$M$2:$M$2500,"MAKUENI",Data!$L$2:$L$2500,$D$3) -> 6 | N29: =IF(C29=0,0,M29/C29) -> 1 | O29: =MAX(C29-M29,0) -> 0 | P29: =IF(C29=0,0,(D29+G29+J29+M29)/(C29*4)) -> 0.95833333
B30: Machakos | C30: =SUMIFS(Data!$P$2:$P$2500,Data!$N$2:$N$2500,"Cluster 5",Data!$M$2:$M$2500,"MACHAKOS") -> 4 | D30: =SUMIFS(Data!$O$2:$O$2500,Data!$F$2:$F$2500,"C&T",Data!$N$2:$N$2500,"Cluster 5",Data!$M$2:$M$2500,"MACHAKOS",Data!$L$2:$L$2500,$D$3) -> 4 | E30: =IF(C30=0,0,D30/C30) -> 1 | F30: =MAX(C30-D30,0) -> 0 | G30: =SUMIFS(Data!$O$2:$O$2500,Data!$F$2:$F$2500,"HTS",Data!$N$2:$N$2500,"Cluster 5",Data!$M$2:$M$2500,"MACHAKOS",Data!$L$2:$L$2500,$D$3) -> 4 | H30: =IF(C30=0,0,G30/C30) -> 1 | I30: =MAX(C30-G30,0) -> 0 | J30: =SUMIFS(Data!$O$2:$O$2500,Data!$F$2:$F$2500,"MNCH",Data!$N$2:$N$2500,"Cluster 5",Data!$M$2:$M$2500,"MACHAKOS",Data!$L$2:$L$2500,$D$3) -> 4 | K30: =IF(C30=0,0,J30/C30) -> 1 | L30: =MAX(C30-J30,0) -> 0 | M30: =SUMIFS(Data!$O$2:$O$2500,Data!$F$2:$F$2500,"PREP",Data!$N$2:$N$2500,"Cluster 5",Data!$M$2:$M$2500,"MACHAKOS",Data!$L$2:$L$2500,$D$3) -> 4 | N30: =IF(C30=0,0,M30/C30) -> 1 | O30: =MAX(C30-M30,0) -> 0 | P30: =IF(C30=0,0,(D30+G30+J30+M30)/(C30*4)) -> 1
B31: CHAK DARAJA TOTAL | C31: =C11+C14+C19+C23+C27 -> 208 | D31: =D11+D14+D19+D23+D27 -> 208 | E31: =IF(C31=0,0,D31/C31) -> 1 | F31: =MAX(C31-D31,0) -> 0 | G31: =G11+G14+G19+G23+G27 -> 193 | H31: =IF(C31=0,0,G31/C31) -> 0.92788462 | I31: =MAX(C31-G31,0) -> 15 | J31: =J11+J14+J19+J23+J27 -> 179 | K31: =IF(C31=0,0,J31/C31) -> 0.86057692 | L31: =MAX(C31-J31,0) -> 29 | M31: =M11+M14+M19+M23+M27 -> 164 | N31: =IF(C31=0,0,M31/C31) -> 0.78846154 | O31: =MAX(C31-M31,0) -> 44 | P31: =IF(C31=0,0,(D31+G31+J31+M31)/(C31*4)) -> 0.89423077
B38: CLUSTER COMPARISON — % of expected sites uploaded
B39: Cluster | C39: Expected Sites | D39: Care & Treatment | E39: HTS | F39: MNCH | G39: PrEP | H39: Overall %
B40: =B11 -> Cluster 1 | C40: =C11 -> 65 | D40: =E11 -> 1 | E40: =H11 -> 0.87692308 | F40: =K11 -> 0.84615385 | G40: =N11 -> 0.58461538 | H40: =P11 -> 0.82692308
B41: =B14 -> Cluster 2 | C41: =C14 -> 64 | D41: =E14 -> 1 | E41: =H14 -> 0.9375 | F41: =K14 -> 0.828125 | G41: =N14 -> 0.796875 | H41: =P14 -> 0.890625
B42: =B19 -> Cluster 3 | C42: =C19 -> 13 | D42: =E19 -> 1 | E42: =H19 -> 1 | F42: =K19 -> 0.92307692 | G42: =N19 -> 1 | H42: =P19 -> 0.98076923
B43: =B23 -> Cluster 4 | C43: =C23 -> 42 | D43: =E23 -> 1 | E43: =H23 -> 0.92857143 | F43: =K23 -> 0.92857143 | G43: =N23 -> 0.92857143 | H43: =P23 -> 0.94642857
B44: =B27 -> Cluster 5 | C44: =C27 -> 24 | D44: =E27 -> 1 | E44: =H27 -> 1 | F44: =K27 -> 0.83333333 | G44: =N27 -> 0.95833333 | H44: =P27 -> 0.94791667
B45: Chak Daraja | C45: =C31 -> 208 | D45: =E31 -> 1 | E45: =H31 -> 0.92788462 | F45: =K31 -> 0.86057692 | G45: =N31 -> 0.78846154 | H45: =P31 -> 0.89423077

Sheet FAA Milestone Link
B1: FAA MILESTONE LINK — DWAPI UPLOADS vs PAYMENT
B2: Links the cluster upload tracker to the FAA milestone on electronic reporting, and shows the payment tier the current upload rate would earn.
B4: A. Milestone details (from FAA plan)
B5: Milestone ID | C5: 22 | D5: ← change to link another milestone ID from the FAA plan
B6: Milestone name | C6: =IFERROR(INDEX('FAA Milestones'!$B$5:$B$30,MATCH($C$5,'FAA Milestones'!$A$5:$A$30,0)),"") -> Digital Health Systems & Electronic Reporting Coverage, Data Systems
B7: Description | C7: =IFERROR(INDEX('FAA Milestones'!$E$5:$E$30,MATCH($C$5,'FAA Milestones'!$A$5:$A$30,0)),"") -> Electronic reporting of HIV service data through TaifaCare EMR, automated exchange to the National Data Warehouse and KHIS
B8: Data source | C8: =IFERROR(INDEX('FAA Milestones'!$F$5:$F$30,MATCH($C$5,'FAA Milestones'!$A$5:$A$30,0)),"") -> National Data Warehouse (NDWH); KHIS
B9: Verification method | C9: =IFERROR(INDEX('FAA Milestones'!$H$5:$H$30,MATCH($C$5,'FAA Milestones'!$A$5:$A$30,0)),"") -> Desk review of the National Data Warehouse system-generated facility reporting-rate dashboard and KHIS reporting completeness; district Data Quality Assessment (DQA)
B10: Achievement threshold | C10: =IFERROR(INDEX('FAA Milestones'!$I$5:$I$30,MATCH($C$5,'FAA Milestones'!$A$5:$A$30,0)),"") -> ≥95% of HIV facilities reporting electronically
B11: Payment scale | C11: =IFERROR(INDEX('FAA Milestones'!$J$5:$J$30,MATCH($C$5,'FAA Milestones'!$A$5:$A$30,0)),"") -> 100% payment: ≥95% reporting 80% payment: 90–94% reporting 50% payment: 80–89% reporting No payment: <80% reporting
B12: Frequency | C12: =IFERROR(INDEX('FAA Milestones'!$K$5:$K$30,MATCH($C$5,'FAA Milestones'!$A$5:$A$30,0)),"") -> Monthly
B13: Type / Tier | C13: =IFERROR(INDEX('FAA Milestones'!$V$5:$V$30,MATCH($C$5,'FAA Milestones'!$A$5:$A$30,0)),"") -> Tier 2
B14: Verified by | C14: =IFERROR(INDEX('FAA Milestones'!$U$5:$U$30,MATCH($C$5,'FAA Milestones'!$A$5:$A$30,0)),"") -> Hybrid (USG + Third Party Firm)
B15: Max annual payment ($) | C15: =IFERROR(INDEX('FAA Milestones'!$T$5:$T$30,MATCH($C$5,'FAA Milestones'!$A$5:$A$30,0)),"") -> 269684
B17: B. Payment tiers (from the FAA payment scale — edit if renegotiated)
B18: Minimum reporting rate | C18: Payment % | D18: Tier label
B19: 0 | C19: 0 | D19: No payment (<80%)
B20: 0.8 | C20: 0.5 | D20: 50% payment (80–89%)
B21: 0.9 | C21: 0.8 | D21: 80% payment (90–94%)
B22: 0.95 | C22: 1 | D22: Full payment (≥95%)
B23: Read as: a rate at or above the minimum earns that payment %. Lookup uses the highest tier met.
B25: C. Current period — performance against the milestone
B26: Reporting period | C26: ='Cluster Summary'!D2 -> 46266
B27: Upload month | C27: ='Cluster Summary'!D3 -> 2026-10
B28: Measure used for payment | C28: C&T | D28: ← pick which upload rate GOR will treat as "HIV facilities reporting electronically" (C&T = NDWH C&T facility reporting rate)
B30: Docket | C30: Expected Sites | D30: Sites Uploaded | E30: Reporting Rate | F30: Payment Tier | G30: Sites still needed for 95%
B31: C&T | C31: ='Cluster Summary'!C31 -> 208 | D31: ='Cluster Summary'!D31 -> 208 | E31: =IF(C31=0,0,D31/C31) -> 1 | F31: =INDEX($D$19:$D$22,MATCH(E31,$B$19:$B$22,1)) -> Full payment (≥95%) | G31: =MAX(0,ROUNDUP($B$22*C31,0)-D31) -> 0
B32: HTS | C32: ='Cluster Summary'!C31 -> 208 | D32: ='Cluster Summary'!G31 -> 193 | E32: =IF(C32=0,0,D32/C32) -> 0.92788462 | F32: =INDEX($D$19:$D$22,MATCH(E32,$B$19:$B$22,1)) -> 80% payment (90–94%) | G32: =MAX(0,ROUNDUP($B$22*C32,0)-D32) -> 5
B33: MNCH | C33: ='Cluster Summary'!C31 -> 208 | D33: ='Cluster Summary'!J31 -> 179 | E33: =IF(C33=0,0,D33/C33) -> 0.86057692 | F33: =INDEX($D$19:$D$22,MATCH(E33,$B$19:$B$22,1)) -> 50% payment (80–89%) | G33: =MAX(0,ROUNDUP($B$22*C33,0)-D33) -> 19
B34: PrEP | C34: ='Cluster Summary'!C31 -> 208 | D34: ='Cluster Summary'!M31 -> 164 | E34: =IF(C34=0,0,D34/C34) -> 0.78846154 | F34: =INDEX($D$19:$D$22,MATCH(E34,$B$19:$B$22,1)) -> No payment (<80%) | G34: =MAX(0,ROUNDUP($B$22*C34,0)-D34) -> 34
B35: Overall | C35: =SUM(C31:C34) -> 832 | D35: =SUM(D31:D34) -> 744 | E35: =IF(C35=0,0,D35/C35) -> 0.89423077 | F35: =INDEX($D$19:$D$22,MATCH(E35,$B$19:$B$22,1)) -> 50% payment (80–89%) | G35: =MAX(0,ROUNDUP($B$22*C35,0)-D35) -> 47
B37: RESULT FOR THIS MILESTONE
B38: Reporting rate (selected measure) | C38: =INDEX($E$31:$E$35,MATCH($C$28,$B$31:$B$35,0)) -> 1
B39: Payment tier earned | C39: =INDEX($D$19:$D$22,MATCH(C38,$B$19:$B$22,1)) -> Full payment (≥95%)
B40: Payment % earned | C40: =INDEX($C$19:$C$22,MATCH(C38,$B$19:$B$22,1)) -> 1
B41: Reference monthly max payment ($) — M2–M6 rate | C41: =IFERROR(INDEX('FAA Milestones'!$O$5:$O$30,MATCH($C$5,'FAA Milestones'!$A$5:$A$30,0)),0) -> 44900
B42: Indicative payment at this rate ($) | C42: =C40*C41 -> 44900
B43: Amount at risk ($) | C43: =C41-C42 -> 0
B44: Sites still needed to reach 95% | C44: =INDEX($G$31:$G$35,MATCH($C$28,$B$31:$B$35,0)) -> 0
B45: August 2026 is before the award start (1-Sep-2026), so it is a baseline: the first paid month (M1 = September performance) is uploaded in October 2026.
...

Sheet Facility Tracker
A1: FACILITY UPLOAD STATUS
A2: ="Upload month: "&'Cluster Summary'!D3&" | Complete = uploaded & complete · Incomplete = uploaded but flagged incomplete · Pending = not uploaded · N/A = docket not offered" -> Upload month: 2026-10 | Complete = uploaded & complete · Incomplete = uploaded but flagged incomplete · Pending = not uploaded · N/A = docket not offered
A4: Cluster | B4: County | C4: Sub-county | D4: MFL Code | E4: Facility | F4: Partner | G4: Care & Treatment | H4: HTS | I4: MNCH | J4: PrEP | K4: Dockets Pending
A5: Cluster 1 | B5: Meru | C5: Buuri | D5: 12282 | E5: Kibirichia Sub-District Hospital | F5: USAID Jamii Tekelezi | G5: =IF(COUNTIFS(Data!$A:$A,$D5,Data!$F:$F,"C&T")=0,"N/A",IF(COUNTIFS(Data!$A:$A,$D5,Data!$F:$F,"C&T",Data!$L:$L,'Cluster Summary'!$D$3,Data!$I:$I,"Complete")>0,"Complete",IF(COUNTIFS(Data!$A:$A,$D5,Data!$F:$F,"C&T",Data!$L:$L,'Cluster Summary'!$D$3)>0,"Incomplete","Pending"))) -> Complete | H5: =IF(COUNTIFS(Data!$A:$A,$D5,Data!$F:$F,"HTS")=0,"N/A",IF(COUNTIFS(Data!$A:$A,$D5,Data!$F:$F,"HTS",Data!$L:$L,'Cluster Summary'!$D$3,Data!$I:$I,"Complete")>0,"Complete",IF(COUNTIFS(Data!$A:$A,$D5,Data!$F:$F,"HTS",Data!$L:$L,'Cluster Summary'!$D$3)>0,"Incomplete","Pending"))) -> Complete | I5: =IF(COUNTIFS(Data!$A:$A,$D5,Data!$F:$F,"MNCH")=0,"N/A",IF(COUNTIFS(Data!$A:$A,$D5,Data!$F:$F,"MNCH",Data!$L:$L,'Cluster Summary'!$D$3,Data!$I:$I,"Complete")>0,"Complete",IF(COUNTIFS(Data!$A:$A,$D5,Data!$F:$F,"MNCH",Data!$L:$L,'Cluster Summary'!$D$3)>0,"Incomplete","Pending"))) -> Complete | J5: =IF(COUNTIFS(Data!$A:$A,$D5,Data!$F:$F,"PREP")=0,"N/A",IF(COUNTIFS(Data!$A:$A,$D5,Data!$F:$F,"PREP",Data!$L:$L,'Cluster Summary'!$D$3,Data!$I:$I,"Complete")>0,"Complete",IF(COUNTIFS(Data!$A:$A,$D5,Data!$F:$F,"PREP",Data!$L:$L,'Cluster Summary'!$D$3)>0,"Incomplete","Pending"))) -> Complete | K5: =COUNTIF(G5:J5,"Pending") -> 0
A6: Cluster 1 | B6: Meru | C6: Buuri | D6: 12302 | E6: Kiirua Dispensary | F6: USAID Jamii Tekelezi | G6: =IF(COUNTIFS(Data!$A:$A,$D6,Data!$F:$F,"C&T")=0,"N/A",IF(COUNTIFS(Data!$A:$A,$D6,Data!$F:$F,"C&T",Data!$L:$L,'Cluster Summary'!$D$3,Data!$I:$I,"Complete")>0,"Complete",IF(COUNTIFS(Data!$A:$A,$D6,Data!$F:$F,"C&T",Data!$L:$L,'Cluster Summary'!$D$3)>0,"Incomplete","Pending"))) -> Complete | H6: =IF(COUNTIFS(Data!$A:$A,$D6,Data!$F:$F,"HTS")=0,"N/A",IF(COUNTIFS(Data!$A:$A,$D6,Data!$F:$F,"HTS",Data!$L:$L,'Cluster Summary'!$D$3,Data!$I:$I,"Complete")>0,"Complete",IF(COUNTIFS(Data!$A:$A,$D6,Data!$F:$F,"HTS",Data!$L:$L,'Cluster Summary'!$D$3)>0,"Incomplete","Pending"))) -> Complete | I6: =IF(COUNTIFS(Data!$A:$A,$D6,Data!$F:$F,"MNCH")=0,"N/A",IF(COUNTIFS(Data!$A:$A,$D6,Data!$F:$F,"MNCH",Data!$L:$L,'Cluster Summary'!$D$3,Data!$I:$I,"Complete")>0,"Complete",IF(COUNTIFS(Data!$A:$A,$D6,Data!$F:$F,"MNCH",Data!$L:$L,'Cluster Summary'!$D$3)>0,"Incomplete","Pending"))) -> Incomplete | J6: =IF(COUNTIFS(Data!$A:$A,$D6,Data!$F:$F,"PREP")=0,"N/A",IF(COUNTIFS(Data!$A:$A,$D6,Data!$F:$F,"PREP",Data!$L:$L,'Cluster Summary'!$D$3,Data!$I:$I,"Complete")>0,"Complete",IF(COUNTIFS(Data!$A:$A,$D6,Data!$F:$F,"PREP",Data!$L:$L,'Cluster Summary'!$D$3)>0,"Incomplete","Pending"))) -> Incomplete | K6: =COUNTIF(G6:J6,"Pending") -> 0
A7: Cluster 1 | B7: Meru | C7: Buuri | D7: 12426 | E7: Lewa Downs Dispensary | F7: USAID Jamii Tekelezi | G7: =IF(COUNTIFS(Data!$A:$A,$D7,Data!$F:$F,"C&T")=0,"N/A",IF(COUNTIFS(Data!$A:$A,$D7,Data!$F:$F,"C&T",Data!$L:$L,'Cluster Summary'!$D$3,Data!$I:$I,"Complete")>0,"Complete",IF(COUNTIFS(Data!$A:$A,$D7,Data!$F:$F,"C&T",Data!$L:$L,'Cluster Summary'!$D$3)>0,"Incomplete","Pending"))) -> Complete | H7: =IF(COUNTIFS(Data!$A:$A,$D7,Data!$F:$F,"HTS")=0,"N/A",IF(COUNTIFS(Data!$A:$A,$D7,Data!$F:$F,"HTS",Data!$L:$L,'Cluster Summary'!$D$3,Data!$I:$I,"Complete")>0,"Complete",IF(COUNTIFS(Data!$A:$A,$D7,Data!$F:$F,"HTS",Data!$L:$L,'Cluster Summary'!$D$3)>0,"Incomplete","Pending"))) -> Complete | I7: =IF(COUNTIFS(Data!$A:$A,$D7,Data!$F:$F,"MNCH")=0,"N/A",IF(COUNTIFS(Data!$A:$A,$D7,Data!$F:$F,"MNCH",Data!$L:$L,'Cluster Summary'!$D$3,Data!$I:$I,"Complete")>0,"Complete",IF(COUNTIFS(Data!$A:$A,$D7,Data!$F:$F,"MNCH",Data!$L:$L,'Cluster Summary'!$D$3)>0,"Incomplete","Pending"))) -> Complete | J7: =IF(COUNTIFS(Data!$A:$A,$D7,Data!$F:$F,"PREP")=0,"N/A",IF(COUNTIFS(Data!$A:$A,$D7,Data!$F:$F,"PREP",Data!$L:$L,'Cluster Summary'!$D$3,Data!$I:$I,"Complete")>0,"Complete",IF(COUNTIFS(Data!$A:$A,$D7,Data!$F:$F,"PREP",Data!$L:$L,'Cluster Summary'!$D$3)>0,"Incomplete","Pending"))) -> Complete | K7: =COUNTIF(G7:J7,"Pending") -> 0
A8: Cluster 1 | B8: Meru | C8: Buuri | D8: 17287 | E8: Mboroga Dispensary | F8: USAID Jamii Tekelezi | G8: =IF(COUNTIFS(Data!$A:$A,$D8,Data!$F:$F,"C&T")=0,"N/A",IF(COUNTIFS(Data!$A:$A,$D8,Data!$F:$F,"C&T",Data!$L:$L,'Cluster Summary'!$D$3,Data!$I:$I,"Complete")>0,"Complete",IF(COUNTIFS(Data!$A:$A,$D8,Data!$F:$F,"C&T",Data!$L:$L,'Cluster Summary'!$D$3)>0,"Incomplete","Pending"))) -> Complete | H8: =IF(COUNTIFS(Data!$A:$A,$D8,Data!$F:$F,"HTS")=0,"N/A",IF(COUNTIFS(Data!$A:$A,$D8,Data!$F:$F,"HTS",Data!$L:$L,'Cluster Summary'!$D$3,Data!$I:$I,"Complete")>0,"Complete",IF(COUNTIFS(Data!$A:$A,$D8,Data!$F:$F,"HTS",Data!$L:$L,'Cluster Summary'!$D$3)>0,"Incomplete","Pending"))) -> Complete | I8: =IF(COUNTIFS(Data!$A:$A,$D8,Data!$F:$F,"MNCH")=0,"N/A",IF(COUNTIFS(Data!$A:$A,$D8,Data!$F:$F,"MNCH",Data!$L:$L,'Cluster Summary'!$D$3,Data!$I:$I,"Complete")>0,"Complete",IF(COUNTIFS(Data!$A:$A,$D8,Data!$F:$F,"MNCH",Data!$L:$L,'Cluster Summary'!$D$3)>0,"Incomplete","Pending"))) -> Complete | J8: =IF(COUNTIFS(Data!$A:$A,$D8,Data!$F:$F,"PREP")=0,"N/A",IF(COUNTIFS(Data!$A:$A,$D8,Data!$F:$F,"PREP",Data!$L:$L,'Cluster Summary'!$D$3,Data!$I:$I,"Complete")>0,"Complete",IF(COUNTIFS(Data!$A:$A,$D8,Data!$F:$F,"PREP",Data!$L:$L,'Cluster Summary'!$D$3)>0,"Incomplete","Pending"))) -> N/A | K8: =COUNTIF(G8:J8,"Pending") -> 0
A9: Cluster 1 | B9: Meru | C9: Buuri | D9: 12631 | E9: Naari Health Centre | F9: USAID Jamii Tekelezi | G9: =IF(COUNTIFS(Data!$A:$A,$D9,Data!$F:$F,"C&T")=0,"N/A",IF(COUNTIFS(Data!$A:$A,$D9,Data!$F:$F,"C&T",Data!$L:$L,'Cluster Summary'!$D$3,Data!$I:$I,"Complete")>0,"Complete",IF(COUNTIFS(Data!$A:$A,$D9,Data!$F:$F,"C&T",Data!$L:$L,'Cluster Summary'!$D$3)>0,"Incomplete","Pending"))) -> Complete | H9: =IF(COUNTIFS(Data!$A:$A,$D9,Data!$F:$F,"HTS")=0,"N/A",IF(COUNTIFS(Data!$A:$A,$D9,Data!$F:$F,"HTS",Data!$L:$L,'Cluster Summary'!$D$3,Data!$I:$I,"Complete")>0,"Complete",IF(COUNTIFS(Data!$A:$A,$D9,Data!$F:$F,"HTS",Data!$L:$L,'Cluster Summary'!$D$3)>0,"Incomplete","Pending"))) -> Complete | I9: =IF(COUNTIFS(Data!$A:$A,$D9,Data!$F:$F,"MNCH")=0,"N/A",IF(COUNTIFS(Data!$A:$A,$D9,Data!$F:$F,"MNCH",Data!$L:$L,'Cluster Summary'!$D$3,Data!$I:$I,"Complete")>0,"Complete",IF(COUNTIFS(Data!$A:$A,$D9,Data!$F:$F,"MNCH",Data!$L:$L,'Cluster Summary'!$D$3)>0,"Incomplete","Pending"))) -> Complete | J9: =IF(COUNTIFS(Data!$A:$A,$D9,Data!$F:$F,"PREP")=0,"N/A",IF(COUNTIFS(Data!$A:$A,$D9,Data!$F:$F,"PREP",Data!$L:$L,'Cluster Summary'!$D$3,Data!$I:$I,"Complete")>0,"Complete",IF(COUNTIFS(Data!$A:$A,$D9,Data!$F:$F,"PREP",Data!$L:$L,'Cluster Summary'!$D$3)>0,"Incomplete","Pending"))) -> Pending | K9: =COUNTIF(G9:J9,"Pending") -> 1
A10: Cluster 1 | B10: Meru | C10: Buuri | D10: 12700 | E10: Ontulili Dispensary | F10: USAID Jamii Tekelezi | G10: =IF(COUNTIFS(Data!$A:$A,$D10,Data!$F:$F,"C&T")=0,"N/A",IF(COUNTIFS(Data!$A:$A,$D10,Data!$F:$F,"C&T",Data!$L:$L,'Cluster Summary'!$D$3,Data!$I:$I,"Complete")>0,"Complete",IF(COUNTIFS(Data!$A:$A,$D10,Data!$F:$F,"C&T",Data!$L:$L,'Cluster Summary'!$D$3)>0,"Incomplete","Pending"))) -> Complete | H10: =IF(COUNTIFS(Data!$A:$A,$D10,Data!$F:$F,"HTS")=0,"N/A",IF(COUNTIFS(Data!$A:$A,$D10,Data!$F:$F,"HTS",Data!$L:$L,'Cluster Summary'!$D$3,Data!$I:$I,"Complete")>0,"Complete",IF(COUNTIFS(Data!$A:$A,$D10,Data!$F:$F,"HTS",Data!$L:$L,'Cluster Summary'!$D$3)>0,"Incomplete","Pending"))) -> Complete | I10: =IF(COUNTIFS(Data!$A:$A,$D10,Data!$F:$F,"MNCH")=0,"N/A",IF(COUNTIFS(Data!$A:$A,$D10,Data!$F:$F,"MNCH",Data!$L:$L,'Cluster Summary'!$D$3,Data!$I:$I,"Complete")>0,"Complete",IF(COUNTIFS(Data!$A:$A,$D10,Data!$F:$F,"MNCH",Data!$L:$L,'Cluster Summary'!$D$3)>0,"Incomplete","Pending"))) -> N/A | J10: =IF(COUNTIFS(Data!$A:$A,$D10,Data!$F:$F,"PREP")=0,"N/A",IF(COUNTIFS(Data!$A:$A,$D10,Data!$F:$F,"PREP",Data!$L:$L,'Cluster Summary'!$D$3,Data!$I:$I,"Complete")>0,"Complete",IF(COUNTIFS(Data!$A:$A,$D10,Data!$F:$F,"PREP",Data!$L:$L,'Cluster Summary'!$D$3)>0,"Incomplete","Pending"))) -> Pending | K10: =COUNTIF(G10:J10,"Pending") -> 1
A11: Cluster 1 | B11: Meru | C11: Buuri | D11: 12717 | E11: Ruiri Rural Health Demonstration Centre | F11: USAID Jamii Tekelezi | G11: =IF(COUNTIFS(Data!$A:$A,$D11,Data!$F:$F,"C&T")=0,"N/A",IF(COUNTIFS(Data!$A:$A,$D11,Data!$F:$F,"C&T",Data!$L:$L,'Cluster Summary'!$D$3,Data!$I:$I,"Complete")>0,"Complete",IF(COUNTIFS(Data!$A:$A,$D11,Data!$F:$F,"C&T",Data!$L:$L,'Cluster Summary'!$D$3)>0,"Incomplete","Pending"))) -> Complete | H11: =IF(COUNTIFS(Data!$A:$A,$D11,Data!$F:$F,"HTS")=0,"N/A",IF(COUNTIFS(Data!$A:$A,$D11,Data!$F:$F,"HTS",Data!$L:$L,'Cluster Summary'!$D$3,Data!$I:$I,"Complete")>0,"Complete",IF(COUNTIFS(Data!$A:$A,$D11,Data!$F:$F,"HTS",Data!$L:$L,'Cluster Summary'!$D$3)>0,"Incomplete","Pending"))) -> Complete | I11: =IF(COUNTIFS(Data!$A:$A,$D11,Data!$F:$F,"MNCH")=0,"N/A",IF(COUNTIFS(Data!$A:$A,$D11,Data!$F:$F,"MNCH",Data!$L:$L,'Cluster Summary'!$D$3,Data!$I:$I,"Complete")>0,"Complete",IF(COUNTIFS(Data!$A:$A,$D11,Data!$F:$F,"MNCH",Data!$L:$L,'Cluster Summary'!$D$3)>0,"Incomplete","Pending"))) -> Complete | J11: =IF(COUNTIFS(Data!$A:$A,$D11,Data!$F:$F,"PREP")=0,"N/A",IF(COUNTIFS(Data!$A:$A,$D11,Data!$F:$F,"PREP",Data!$L:$L,'Cluster Summary'!$D$3,Data!$I:$I,"Complete")>0,"Complete",IF(COUNTIFS(Data!$A:$A,$D11,Data!$F:$F,"PREP",Data!$L:$L,'Cluster Summary'!$D$3)>0,"Incomplete","Pending"))) -> N/A | K11: =COUNTIF(G11:J11,"Pending") -> 0
A12: Cluster 1 | B12: Meru | C12: Buuri | D12: 12303 | E12: St Theresa Hospital (Kiirua) | F12: USAID Jamii Tekelezi | G12: =IF(COUNTIFS(Data!$A:$A,$D12,Data!$F:$F,"C&T")=0,"N/A",IF(COUNTIFS(Data!$A:$A,$D12,Data!$F:$F,"C&T",Data!$L:$L,'Cluster Summary'!$D$3,Data!$I:$I,"Complete")>0,"Complete",IF(COUNTIFS(Data!$A:$A,$D12,Data!$F:$F,"C&T",Data!$L:$L,'Cluster Summary'!$D$3)>0,"Incomplete","Pending"))) -> Complete | H12: =IF(COUNTIFS(Data!$A:$A,$D12,Data!$F:$F,"HTS")=0,"N/A",IF(COUNTIFS(Data!$A:$A,$D12,Data!$F:$F,"HTS",Data!$L:$L,'Cluster Summary'!$D$3,Data!$I:$I,"Complete")>0,"Complete",IF(COUNTIFS(Data!$A:$A,$D12,Data!$F:$F,"HTS",Data!$L:$L,'Cluster Summary'!$D$3)>0,"Incomplete","Pending"))) -> Complete | I12: =IF(COUNTIFS(Data!$A:$A,$D12,Data!$F:$F,"MNCH")=0,"N/A",IF(COUNTIFS(Data!$A:$A,$D12,Data!$F:$F,"MNCH",Data!$L:$L,'Cluster Summary'!$D$3,Data!$I:$I,"Complete")>0,"Complete",IF(COUNTIFS(Data!$A:$A,$D12,Data!$F:$F,"MNCH",Data!$L:$L,'Cluster Summary'!$D$3)>0,"Incomplete","Pending"))) -> Complete | J12: =IF(COUNTIFS(Data!$A:$A,$D12,Data!$F:$F,"PREP")=0,"N/A",IF(COUNTIFS(Data!$A:$A,$D12,Data!$F:$F,"PREP",Data!$L:$L,'Cluster Summary'!$D$3,Data!$I:$I,"Complete")>0,"Complete",IF(COUNTIFS(Data!$A:$A,$D12,Data!$F:$F,"PREP",Data!$L:$L,'Cluster Summary'!$D$3)>0,"Incomplete","Pending"))) -> Complete | K12: =COUNTIF(G12:J12,"Pending") -> 0
A13: Cluster 1 | B13: Meru | C13: Buuri | D13: 12802 | E13: Timau Sub-County Hospital | F13: USAID Jamii Tekelezi | G13: =IF(COUNTIFS(Data!$A:$A,$D13,Data!$F:$F,"C&T")=0,"N/A",IF(COUNTIFS(Data!$A:$A,$D13,Data!$F:$F,"C&T",Data!$L:$L,'Cluster Summary'!$D$3,Data!$I:$I,"Complete")>0,"Complete",IF(COUNTIFS(Data!$A:$A,$D13,Data!$F:$F,"C&T",Data!$L:$L,'Cluster Summary'!$D$3)>0,"Incomplete","Pending"))) -> Complete | H13: =IF(COUNTIFS(Data!$A:$A,$D13,Data!$F:$F,"HTS")=0,"N/A",IF(COUNTIFS(Data!$A:$A,$D13,Data!$F:$F,"HTS",Data!$L:$L,'Cluster Summary'!$D$3,Data!$I:$I,"Complete")>0,"Complete",IF(COUNTIFS(Data!$A:$A,$D13,Data!$F:$F,"HTS",Data!$L:$L,'Cluster Summary'!$D$3)>0,"Incomplete","Pending"))) -> Complete | I13: =IF(COUNTIFS(Data!$A:$A,$D13,Data!$F:$F,"MNCH")=0,"N/A",IF(COUNTIFS(Data!$A:$A,$D13,Data!$F:$F,"MNCH",Data!$L:$L,'Cluster Summary'!$D$3,Data!$I:$I,"Complete")>0,"Complete",IF(COUNTIFS(Data!$A:$A,$D13,Data!$F:$F,"MNCH",Data!$L:$L,'Cluster Summary'!$D$3)>0,"Incomplete","Pending"))) -> Complete | J13: =IF(COUNTIFS(Data!$A:$A,$D13,Data!$F:$F,"PREP")=0,"N/A",IF(COUNTIFS(Data!$A:$A,$D13,Data!$F:$F,"PREP",Data!$L:$L,'Cluster Summary'!$D$3,Data!$I:$I,"Complete")>0,"Complete",IF(COUNTIFS(Data!$A:$A,$D13,Data!$F:$F,"PREP",Data!$L:$L,'Cluster Summary'!$D$3)>0,"Incomplete","Pending"))) -> Complete | K13: =COUNTIF(G13:J13,"Pending") -> 0
A14: Cluster 1 | B14: Meru | C14: Igembe Central | D14: 12174 | E14: Kangeta Heaith Centre | F14: USAID Jamii Tekelezi | G14: =IF(COUNTIFS(Data!$A:$A,$D14,Data!$F:$F,"C&T")=0,"N/A",IF(COUNTIFS(Data!$A:$A,$D14,Data!$F:$F,"C&T",Data!$L:$L,'Cluster Summary'!$D$3,Data!$I:$I,"Complete")>0,"Complete",IF(COUNTIFS(Data!$A:$A,$D14,Data!$F:$F,"C&T",Data!$L:$L,'Cluster Summary'!$D$3)>0,"Incomplete","Pending"))) -> Complete | H14: =IF(COUNTIFS(Data!$A:$A,$D14,Data!$F:$F,"HTS")=0,"N/A",IF(COUNTIFS(Data!$A:$A,$D14,Data!$F:$F,"HTS",Data!$L:$L,'Cluster Summary'!$D$3,Data!$I:$I,"Complete")>0,"Complete",IF(COUNTIFS(Data!$A:$A,$D14,Data!$F:$F,"HTS",Data!$L:$L,'Cluster Summary'!$D$3)>0,"Incomplete","Pending"))) -> Complete | I14: =IF(COUNTIFS(Data!$A:$A,$D14,Data!$F:$F,"MNCH")=0,"N/A",IF(COUNTIFS(Data!$A:$A,$D14,Data!$F:$F,"MNCH",Data!$L:$L,'Cluster Summary'!$D$3,Data!$I:$I,"Complete")>0,"Complete",IF(COUNTIFS(Data!$A:$A,$D14,Data!$F:$F,"MNCH",Data!$L:$L,'Cluster Summary'!$D$3)>0,"Incomplete","Pending"))) -> Complete | J14: =IF(COUNTIFS(Data!$A:$A,$D14,Data!$F:$F,"PREP")=0,"N/A",IF(COUNTIFS(Data!$A:$A,$D14,Data!$F:$F,"PREP",Data!$L:$L,'Cluster Summary'!$D$3,Data!$I:$I,"Complete")>0,"Complete",IF(COUNTIFS(Data!$A:$A,$D14,Data!$F:$F,"PREP",Data!$L:$L,'Cluster Summary'!$D$3)>0,"Incomplete","Pending"))) -> Pending | K14: =COUNTIF(G14:J14,"Pending") -> 1
A15: Cluster 1 | B15: Meru | C15: Igembe Central | D15: 17262 | E15: Kawiru Dispensary | F15: USAID Jamii Tekelezi | G15: =IF(COUNTIFS(Data!$A:$A,$D15,Data!$F:$F,"C&T")=0,"N/A",IF(COUNTIFS(Data!$A:$A,$D15,Data!$F:$F,"C&T",Data!$L:$L,'Cluster Summary'!$D$3,Data!$I:$I,"Complete")>0,"Complete",IF(COUNTIFS(Data!$A:$A,$D15,Data!$F:$F,"C&T",Data!$L:$L,'Cluster Summary'!$D$3)>0,"Incomplete","Pending"))) -> Complete | H15: =IF(COUNTIFS(Data!$A:$A,$D15,Data!$F:$F,"HTS")=0,"N/A",IF(COUNTIFS(Data!$A:$A,$D15,Data!$F:$F,"HTS",Data!$L:$L,'Cluster Summary'!$D$3,Data!$I:$I,"Complete")>0,"Complete",IF(COUNTIFS(Data!$A:$A,$D15,Data!$F:$F,"HTS",Data!$L:$L,'Cluster Summary'!$D$3)>0,"Incomplete","Pending"))) -> Complete | I15: =IF(COUNTIFS(Data!$A:$A,$D15,Data!$F:$F,"MNCH")=0,"N/A",IF(COUNTIFS(Data!$A:$A,$D15,Data!$F:$F,"MNCH",Data!$L:$L,'Cluster Summary'!$D$3,Data!$I:$I,"Complete")>0,"Complete",IF(COUNTIFS(Data!$A:$A,$D15,Data!$F:$F,"MNCH",Data!$L:$L,'Cluster Summary'!$D$3)>0,"Incomplete","Pending"))) -> N/A | J15: =IF(COUNTIFS(Data!$A:$A,$D15,Data!$F:$F,"PREP")=0,"N/A",IF(COUNTIFS(Data!$A:$A,$D15,Data!$F:$F,"PREP",Data!$L:$L,'Cluster Summary'!$D$3,Data!$I:$I,"Complete")>0,"Complete",IF(COUNTIFS(Data!$A:$A,$D15,Data!$F:$F,"PREP",Data!$L:$L,'Cluster Summary'!$D$3)>0,"Incomplete","Pending"))) -> N/A | K15: =COUNTIF(G15:J15,"Pending") -> 0
A16: Cluster 1 | B16: Meru | C16: Igembe Central | D16: 12319 | E16: Kina Dispensary | F16: USAID Jamii Tekelezi | G16: =IF(COUNTIFS(Data!$A:$A,$D16,Data!$F:$F,"C&T")=0,"N/A",IF(COUNTIFS(Data!$A:$A,$D16,Data!$F:$F,"C&T",Data!$L:$L,'Cluster Summary'!$D$3,Data!$I:$I,"Complete")>0,"Complete",IF(COUNTIFS(Data!$A:$A,$D16,Data!$F:$F,"C&T",Data!$L:$L,'Cluster Summary'!$D$3)>0,"Incomplete","Pending"))) -> Complete | H16: =IF(COUNTIFS(Data!$A:$A,$D16,Data!$F:$F,"HTS")=0,"N/A",IF(COUNTIFS(Data!$A:$A,$D16,Data!$F:$F,"HTS",Data!$L:$L,'Cluster Summary'!$D$3,Data!$I:$I,"Complete")>0,"Complete",IF(COUNTIFS(Data!$A:$A,$D16,Data!$F:$F,"HTS",Data!$L:$L,'Cluster Summary'!$D$3)>0,"Incomplete","Pending"))) -> Complete | I16: =IF(COUNTIFS(Data!$A:$A,$D16,Data!$F:$F,"MNCH")=0,"N/A",IF(COUNTIFS(Data!$A:$A,$D16,Data!$F:$F,"MNCH",Data!$L:$L,'Cluster Summary'!$D$3,Data!$I:$I,"Complete")>0,"Complete",IF(COUNTIFS(Data!$A:$A,$D16,Data!$F:$F,"MNCH",Data!$L:$L,'Cluster Summary'!$D$3)>0,"Incomplete","Pending"))) -> Complete | J16: =IF(COUNTIFS(Data!$A:$A,$D16,Data!$F:$F,"PREP")=0,"N/A",IF(COUNTIFS(Data!$A:$A,$D16,Data!$F:$F,"PREP",Data!$L:$L,'Cluster Summary'!$D$3,Data!$I:$I,"Complete")>0,"Complete",IF(COUNTIFS(Data!$A:$A,$D16,Data!$F:$F,"PREP",Data!$L:$L,'Cluster Summary'!$D$3)>0,"Incomplete","Pending"))) -> Complete | K16: =COUNTIF(G16:J16,"Pending") -> 0
... A212: Cluster 5 | B212: Machakos | C212: Yatta | D212: 12489 | E212: Matuu Mission Health Centre | F212: CHAK CHAP STAWISHA | G212: =IF(COUNTIFS(Data!$A:$A,$D212,Data!$F:$F,"C&T")=0,"N/A",IF(COUNTIFS(Data!$A:$A,$D212,Data!$F:$F,"C&T",Data!$L:$L,'Cluster Summary'!$D$3,Data!$I:$I,"Complete")>0,"Complete",IF(COUNTIFS(Data!$A:$A,$D212,Data!$F:$F,"C&T",Data!$L:$L,'Cluster Summary'!$D$3)>0,"Incomplete","Pending"))) -> Complete | H212: =IF(COUNTIFS(Data!$A:$A,$D212,Data!$F:$F,"HTS")=0,"N/A",IF(COUNTIFS(Data!$A:$A,$D212,Data!$F:$F,"HTS",Data!$L:$L,'Cluster Summary'!$D$3,Data!$I:$I,"Complete")>0,"Complete",IF(COUNTIFS(Data!$A:$A,$D212,Data!$F:$F,"HTS",Data!$L:$L,'Cluster Summary'!$D$3)>0,"Incomplete","Pending"))) -> Complete | I212: =IF(COUNTIFS(Data!$A:$A,$D212,Data!$F:$F,"MNCH")=0,"N/A",IF(COUNTIFS(Data!$A:$A,$D212,Data!$F:$F,"MNCH",Data!$L:$L,'Cluster Summary'!$D$3,Data!$I:$I,"Complete")>0,"Complete",IF(COUNTIFS(Data!$A:$A,$D212,Data!$F:$F,"MNCH",Data!$L:$L,'Cluster Summary'!$D$3)>0,"Incomplete","Pending"))) -> Complete | J212: =IF(COUNTIFS(Data!$A:$A,$D212,Data!$F:$F,"PREP")=0,"N/A",IF(COUNTIFS(Data!$A:$A,$D212,Data!$F:$F,"PREP",Data!$L:$L,'Cluster Summary'!$D$3,Data!$I:$I,"Complete")>0,"Complete",IF(COUNTIFS(Data!$A:$A,$D212,Data!$F:$F,"PREP",Data!$L:$L,'Cluster Summary'!$D$3)>0,"Incomplete","Pending"))) -> Complete | K212: =COUNTIF(G212:J212,"Pending") -> 0

Sheet Live Data
B1: LIVE DATA CONNECTION — SPOT / DWAPI
B2: Option 1 (active): the tracker reads the newest SPOT export saved in one folder. Click Data → Refresh All and every sheet updates.
B4: 1. Settings
B5: SPOT export folder (full path) | C5: W:\Dwapi Uploads\SPOT Exports
B6: Rows currently loaded | C6: =COUNTIF(Data!$A$2:$A$2500,">0") -> 1115
B7: Upload months present | C7: =COUNTIF(Data!$L$2:$L$2500,'Cluster Summary'!$D$3)&" rows in "&'Cluster Summary'!$D$3&" (selected upload month)" -> 750 rows in 2026-10 (selected upload month)
B8: Source file loaded | C8: =IFERROR(INDEX(SPOT_Import!$A$2:$Z$2,MATCH("Source File",SPOT_Import!$A$1:$Z$1,0)),"(pasted data)") -> download (39).csv
B10: 2. Column check (SPOT_Import headers)
B11: Tracker field | C11: Column # in SPOT_Import | D11: Status
B12: Code | C12: =IFERROR(MATCH(B12,SPOT_Import!$1:$1,0),99) -> 1 | D12: =IF(C12=99,"✗ missing — rename the header in SPOT_Import","✓ found") -> ✓ found
B13: Facility | C13: =IFERROR(MATCH(B13,SPOT_Import!$1:$1,0),99) -> 2 | D13: =IF(C13=99,"✗ missing — rename the header in SPOT_Import","✓ found") -> ✓ found
B14: County | C14: =IFERROR(MATCH(B14,SPOT_Import!$1:$1,0),99) -> 3 | D14: =IF(C14=99,"✗ missing — rename the header in SPOT_Import","✓ found") -> ✓ found
B15: Sub-county | C15: =IFERROR(MATCH(B15,SPOT_Import!$1:$1,0),99) -> 4 | D15: =IF(C15=99,"✗ missing — rename the header in SPOT_Import","✓ found") -> ✓ found
B16: Partner | C16: =IFERROR(MATCH(B16,SPOT_Import!$1:$1,0),99) -> 5 | D16: =IF(C16=99,"✗ missing — rename the header in SPOT_Import","✓ found") -> ✓ found
B17: Docket | C17: =IFERROR(MATCH(B17,SPOT_Import!$1:$1,0),99) -> 6 | D17: =IF(C17=99,"✗ missing — rename the header in SPOT_Import","✓ found") -> ✓ found
B18: Expected | C18: =IFERROR(MATCH(B18,SPOT_Import!$1:$1,0),99) -> 7 | D18: =IF(C18=99,"✗ missing — rename the header in SPOT_Import","✓ found") -> ✓ found
B19: Received | C19: =IFERROR(MATCH(B19,SPOT_Import!$1:$1,0),99) -> 8 | D19: =IF(C19=99,"✗ missing — rename the header in SPOT_Import","✓ found") -> ✓ found
B20: Status | C20: =IFERROR(MATCH(B20,SPOT_Import!$1:$1,0),99) -> 9 | D20: =IF(C20=99,"✗ missing — rename the header in SPOT_Import","✓ found") -> ✓ found
B21: Updated | C21: =IFERROR(MATCH(B21,SPOT_Import!$1:$1,0),99) -> 10 | D21: =IF(C21=99,"✗ missing — rename the header in SPOT_Import","✓ found") -> ✓ found
B22: logDate | C22: =IFERROR(MATCH(B22,SPOT_Import!$1:$1,0),99) -> 11 | D22: =IF(C22=99,"✗ missing — rename the header in SPOT_Import","✓ found") -> ✓ found
B24: 3. One-time setup in Excel (about 5 minutes, Excel 2016 / Microsoft 365 on Windows)
B25: Step 1 | C25: Create a folder for SPOT exports (e.g. Documents\SPOT Exports) and type its full path in the yellow cell C5 above.
B26: Step 2 | C26: Download the facility upload list from SPOT as usual and save it in that folder (.xlsx or .csv). Keep old files if you like — the newest one is used.
B27: Step 3 | C27: In Excel: Data → Get Data → From Other Sources → Blank Query. In the Power Query window click Advanced Editor.
B28: Step 4 | C28: Delete everything in the editor, paste the code in section 4 below (cells B36:B68, or the SPOT_Feed_PowerQuery.txt file), click Done. Rename the query (right pane) to SPOT_Feed.
B29: Step 5 | C29: If asked about privacy levels, choose "Ignore Privacy Levels" (both sources are your own files) or set both to Organizational.
B30: Step 6 | C30: Home → Close & Load To… → Table → Existing worksheet → =SPOT_Import!$A$1. Say OK to replace the sample August data on that sheet.
B31: Step 7 | C31: Data → Queries & Connections → right-click SPOT_Feed → Properties → tick "Refresh data when opening the file" (optional: "Refresh every 60 minutes").
B32: Step 8 | C32: From then on: save the new SPOT export in the folder → Data → Refresh All. Set the reporting period and upload month (yellow cells) on Cluster Summary.
B33: Step 9 | C33: Check section 2 above shows "✓ found" for every field. If SPOT renames a column, fix the header in SPOT_Import or the name list in the query.
B35: 4. Power Query code (SPOT_Feed) — copy cells B36 to B68 into the Advanced Editor
B36: // ===== SPOT_Feed : loads the newest SPOT / DWAPI export from the folder named in the cell "SpotFolder" =====
B37: let
B38: FolderPath = Text.Trim(Text.From(Excel.CurrentWorkbook(){[Name="SpotFolder"]}[Content]{0}[Column1])),
B39: Files = Folder.Files(FolderPath),
B40: Usable = Table.SelectRows(Files, each List.Contains({".xlsx", ".xls", ".csv"}, Text.Lower([Extension]))
B41: and not Text.StartsWith([Name], "~$")),
B42: Latest = Table.First(Table.Sort(Usable, {{"Date modified", Order.Descending}})),
B43: Raw =
B44: if Text.Lower(Latest[Extension]) = ".csv" then
...

Sheet Cluster Map
A1: Cluster Map — edit here if a county moves cluster
A3: Cluster | B3: County (as in DWAPI, upper case) | C3: County label
A4: Cluster 1 | B4: MERU | C4: Meru
A5: Cluster 1 | B5: LAIKIPIA | C5: Laikipia
A6: Cluster 2 | B6: EMBU | C6: Embu
A7: Cluster 2 | B7: THARAKA-NITHI | C7: Tharaka-Nithi
A8: Cluster 2 | B8: KIRINYAGA | C8: Kirinyaga
A9: Cluster 2 | B9: NYERI | C9: Nyeri
A10: Cluster 3 | B10: KIAMBU | C10: Kiambu
A11: Cluster 3 | B11: MURANG'A | C11: Murang'a
A12: Cluster 3 | B12: KAJIADO | C12: Kajiado
A13: Cluster 4 | B13: NYANDARUA | C13: Nyandarua
A14: Cluster 4 | B14: NAROK | C14: Narok
... A18: Cluster 5 | B18: MACHAKOS | C18: Machakos
A20: Source: cluster/county allocation from the "Site Census" sheet of IMPROVED VERSION.xlsx. Blue text = editable inputs.

Sheet Data
A1: Code | B1: Facility | C1: County | D1: Sub-county | E1: Partner | F1: Docket | G1: Expected | H1: Received | I1: Status | J1: Updated | K1: logDate | L1: Upload Month | M1: County (clean) | N1: Cluster | O1: Upload Count Flag | P1: Expected Site Flag
A2: =IFERROR(IF(INDEX(SPOT_Import!$A$1:$Z$2488,2,'Live Data'!$C$12)="","",INDEX(SPOT_Import!$A$1:$Z$2488,2,'Live Data'!$C$12)),"") -> 12802 | B2: =IFERROR(IF(INDEX(SPOT_Import!$A$1:$Z$2488,2,'Live Data'!$C$13)="","",INDEX(SPOT_Import!$A$1:$Z$2488,2,'Live Data'!$C$13)),"") -> Timau Sub-District Hospital | C2: =IFERROR(IF(INDEX(SPOT_Import!$A$1:$Z$2488,2,'Live Data'!$C$14)="","",INDEX(SPOT_Import!$A$1:$Z$2488,2,'Live Data'!$C$14)),"") -> MERU | D2: =IFERROR(IF(INDEX(SPOT_Import!$A$1:$Z$2488,2,'Live Data'!$C$15)="","",INDEX(SPOT_Import!$A$1:$Z$2488,2,'Live Data'!$C$15)),"") -> Buuri | E2: =IFERROR(IF(INDEX(SPOT_Import!$A$1:$Z$2488,2,'Live Data'!$C$16)="","",INDEX(SPOT_Import!$A$1:$Z$2488,2,'Live Data'!$C$16)),"") -> USAID Jamii Tekelezi | F2: =IFERROR(IF(INDEX(SPOT_Import!$A$1:$Z$2488,2,'Live Data'!$C$17)="","",INDEX(SPOT_Import!$A$1:$Z$2488,2,'Live Data'!$C$17)),"") -> C&T | G2: =IFERROR(IF(INDEX(SPOT_Import!$A$1:$Z$2488,2,'Live Data'!$C$18)="","",INDEX(SPOT_Import!$A$1:$Z$2488,2,'Live Data'!$C$18)),"") -> 1500 | H2: =IFERROR(IF(INDEX(SPOT_Import!$A$1:$Z$2488,2,'Live Data'!$C$19)="","",INDEX(SPOT_Import!$A$1:$Z$2488,2,'Live Data'!$C$19)),"") -> 1500 | I2: =IFERROR(IF(INDEX(SPOT_Import!$A$1:$Z$2488,2,'Live Data'!$C$20)="","",INDEX(SPOT_Import!$A$1:$Z$2488,2,'Live Data'!$C$20)),"") -> Complete | J2: =IFERROR(IF(INDEX(SPOT_Import!$A$1:$Z$2488,2,'Live Data'!$C$21)="","",INDEX(SPOT_Import!$A$1:$Z$2488,2,'Live Data'!$C$21)),"") -> 2026-10-14T18:22:10.000Z | K2: =IFERROR(IF(INDEX(SPOT_Import!$A$1:$Z$2488,2,'Live Data'!$C$22)="","",INDEX(SPOT_Import!$A$1:$Z$2488,2,'Live Data'!$C$22)),"") -> 2026-10-14T18:22:10.000Z | L2: =IF(A2="","",IF(ISNUMBER(K2),TEXT(K2,"yyyy-mm"),LEFT(K2,7))) -> 2026-10 | M2: =IF(A2="","",UPPER(TRIM(SUBSTITUTE(C2," - ","-")))) -> MERU | N2: =IF(A2="","",IFERROR(INDEX('Cluster Map'!$A$4:$A$38,MATCH(M2,'Cluster Map'!$B$4:$B$38,0)),"Unmapped")) -> Cluster 1 | O2: =IF(A2="",0,IF(COUNTIFS($A$2:A2,A2,$F$2:F2,F2,$L$2:L2,L2)=1,1,0)) -> 1 | P2: =IF(A2="",0,IF(AND(F2="C&T",COUNTIFS($A$2:A2,A2,$F$2:F2,"C&T")=1),1,0)) -> 1
A3: =IFERROR(IF(INDEX(SPOT_Import!$A$1:$Z$2488,3,'Live Data'!$C$12)="","",INDEX(SPOT_Import!$A$1:$Z$2488,3,'Live Data'!$C$12)),"") -> 12719 | B3: =IFERROR(IF(INDEX(SPOT_Import!$A$1:$Z$2488,3,'Live Data'!$C$13)="","",INDEX(SPOT_Import!$A$1:$Z$2488,3,'Live Data'!$C$13)),"") -> Runyenjes District Hospital | C3: =IFERROR(IF(INDEX(SPOT_Import!$A$1:$Z$2488,3,'Live Data'!$C$14)="","",INDEX(SPOT_Import!$A$1:$Z$2488,3,'Live Data'!$C$14)),"") -> EMBU | D3: =IFERROR(IF(INDEX(SPOT_Import!$A$1:$Z$2488,3,'Live Data'!$C$15)="","",INDEX(SPOT_Import!$A$1:$Z$2488,3,'Live Data'!$C$15)),"") -> Runyenjes | E3: =IFERROR(IF(INDEX(SPOT_Import!$A$1:$Z$2488,3,'Live Data'!$C$16)="","",INDEX(SPOT_Import!$A$1:$Z$2488,3,'Live Data'!$C$16)),"") -> USAID Jamii Tekelezi | F3: =IFERROR(IF(INDEX(SPOT_Import!$A$1:$Z$2488,3,'Live Data'!$C$17)="","",INDEX(SPOT_Import!$A$1:$Z$2488,3,'Live Data'!$C$17)),"") -> PREP | G3: =IFERROR(IF(INDEX(SPOT_Import!$A$1:$Z$2488,3,'Live Data'!$C$18)="","",INDEX(SPOT_Import!$A$1:$Z$2488,3,'Live Data'!$C$18)),"") -> 463 | H3: =IFERROR(IF(INDEX(SPOT_Import!$A$1:$Z$2488,3,'Live Data'!$C$19)="","",INDEX(SPOT_Import!$A$1:$Z$2488,3,'Live Data'!$C$19)),"") | I3: =IFERROR(IF(INDEX(SPOT_Import!$A$1:$Z$2488,3,'Live Data'!$C$20)="","",INDEX(SPOT_Import!$A$1:$Z$2488,3,'Live Data'!$C$20)),"") -> Incomplete | J3: =IFERROR(IF(INDEX(SPOT_Import!$A$1:$Z$2488,3,'Live Data'!$C$21)="","",INDEX(SPOT_Import!$A$1:$Z$2488,3,'Live Data'!$C$21)),"") -> 2026-10-14T09:19:24.000Z | K3: =IFERROR(IF(INDEX(SPOT_Import!$A$1:$Z$2488,3,'Live Data'!$C$22)="","",INDEX(SPOT_Import!$A$1:$Z$2488,3,'Live Data'!$C$22)),"") -> 2026-10-14T09:19:24.000Z | L3: =IF(A3="","",IF(ISNUMBER(K3),TEXT(K3,"yyyy-mm"),LEFT(K3,7))) -> 2026-10 | M3: =IF(A3="","",UPPER(TRIM(SUBSTITUTE(C3," - ","-")))) -> EMBU | N3: =IF(A3="","",IFERROR(INDEX('Cluster Map'!$A$4:$A$38,MATCH(M3,'Cluster Map'!$B$4:$B$38,0)),"Unmapped")) -> Cluster 2 | O3: =IF(A3="",0,IF(COUNTIFS($A$2:A3,A3,$F$2:F3,F3,$L$2:L3,L3)=1,1,0)) -> 1 | P3: =IF(A3="",0,IF(AND(F3="C&T",COUNTIFS($A$2:A3,A3,$F$2:F3,"C&T")=1),1,0)) -> 0
A4: =IFERROR(IF(INDEX(SPOT_Import!$A$1:$Z$2488,4,'Live Data'!$C$12)="","",INDEX(SPOT_Import!$A$1:$Z$2488,4,'Live Data'!$C$12)),"") -> 12719 | B4: =IFERROR(IF(INDEX(SPOT_Import!$A$1:$Z$2488,4,'Live Data'!$C$13)="","",INDEX(SPOT_Import!$A$1:$Z$2488,4,'Live Data'!$C$13)),"") -> Runyenjes District Hospital | C4: =IFERROR(IF(INDEX(SPOT_Import!$A$1:$Z$2488,4,'Live Data'!$C$14)="","",INDEX(SPOT_Import!$A$1:$Z$2488,4,'Live Data'!$C$14)),"") -> EMBU | D4: =IFERROR(IF(INDEX(SPOT_Import!$A$1:$Z$2488,4,'Live Data'!$C$15)="","",INDEX(SPOT_Import!$A$1:$Z$2488,4,'Live Data'!$C$15)),"") -> Runyenjes | E4: =IFERROR(IF(INDEX(SPOT_Import!$A$1:$Z$2488,4,'Live Data'!$C$16)="","",INDEX(SPOT_Import!$A$1:$Z$2488,4,'Live Data'!$C$16)),"") -> USAID Jamii Tekelezi | F4: =IFERROR(IF(INDEX(SPOT_Import!$A$1:$Z$2488,4,'Live Data'!$C$17)="","",INDEX(SPOT_Import!$A$1:$Z$2488,4,'Live Data'!$C$17)),"") -> MNCH | G4: =IFERROR(IF(INDEX(SPOT_Import!$A$1:$Z$2488,4,'Live Data'!$C$18)="","",INDEX(SPOT_Import!$A$1:$Z$2488,4,'Live Data'!$C$18)),"") -> 74 | H4: =IFERROR(IF(INDEX(SPOT_Import!$A$1:$Z$2488,4,'Live Data'!$C$19)="","",INDEX(SPOT_Import!$A$1:$Z$2488,4,'Live Data'!$C$19)),"") -> 74 | I4: =IFERROR(IF(INDEX(SPOT_Import!$A$1:$Z$2488,4,'Live Data'!$C$20)="","",INDEX(SPOT_Import!$A$1:$Z$2488,4,'Live Data'!$C$20)),"") -> Complete | J4: =IFERROR(IF(INDEX(SPOT_Import!$A$1:$Z$2488,4,'Live Data'!$C$21)="","",INDEX(SPOT_Import!$A$1:$Z$2488,4,'Live Data'!$C$21)),"") -> 2026-10-14T09:19:00.000Z | K4: =IFERROR(IF(INDEX(SPOT_Import!$A$1:$Z$2488,4,'Live Data'!$C$22)="","",INDEX(SPOT_Import!$A$1:$Z$2488,4,'Live Data'!$C$22)),"") -> 2026-10-14T09:19:00.000Z | L4: =IF(A4="","",IF(ISNUMBER(K4),TEXT(K4,"yyyy-mm"),LEFT(K4,7))) -> 2026-10 | M4: =IF(A4="","",UPPER(TRIM(SUBSTITUTE(C4," - ","-")))) -> EMBU | N4: =IF(A4="","",IFERROR(INDEX('Cluster Map'!$A$4:$A$38,MATCH(M4,'Cluster Map'!$B$4:$B$38,0)),"Unmapped")) -> Cluster 2 | O4: =IF(A4="",0,IF(COUNTIFS($A$2:A4,A4,$F$2:F4,F4,$L$2:L4,L4)=1,1,0)) -> 1 | P4: =IF(A4="",0,IF(AND(F4="C&T",COUNTIFS($A$2:A4,A4,$F$2:F4,"C&T")=1),1,0)) -> 0
A5: =IFERROR(IF(INDEX(SPOT_Import!$A$1:$Z$2488,5,'Live Data'!$C$12)="","",INDEX(SPOT_Import!$A$1:$Z$2488,5,'Live Data'!$C$12)),"") -> 12719 | B5: =IFERROR(IF(INDEX(SPOT_Import!$A$1:$Z$2488,5,'Live Data'!$C$13)="","",INDEX(SPOT_Import!$A$1:$Z$2488,5,'Live Data'!$C$13)),"") -> Runyenjes District Hospital | C5: =IFERROR(IF(INDEX(SPOT_Import!$A$1:$Z$2488,5,'Live Data'!$C$14)="","",INDEX(SPOT_Import!$A$1:$Z$2488,5,'Live Data'!$C$14)),"") -> EMBU | D5: =IFERROR(IF(INDEX(SPOT_Import!$A$1:$Z$2488,5,'Live Data'!$C$15)="","",INDEX(SPOT_Import!$A$1:$Z$2488,5,'Live Data'!$C$15)),"") -> Runyenjes | E5: =IFERROR(IF(INDEX(SPOT_Import!$A$1:$Z$2488,5,'Live Data'!$C$16)="","",INDEX(SPOT_Import!$A$1:$Z$2488,5,'Live Data'!$C$16)),"") -> USAID Jamii Tekelezi | F5: =IFERROR(IF(INDEX(SPOT_Import!$A$1:$Z$2488,5,'Live Data'!$C$17)="","",INDEX(SPOT_Import!$A$1:$Z$2488,5,'Live Data'!$C$17)),"") -> HTS | G5: =IFERROR(IF(INDEX(SPOT_Import!$A$1:$Z$2488,5,'Live Data'!$C$18)="","",INDEX(SPOT_Import!$A$1:$Z$2488,5,'Live Data'!$C$18)),"") -> 4214 | H5: =IFERROR(IF(INDEX(SPOT_Import!$A$1:$Z$2488,5,'Live Data'!$C$19)="","",INDEX(SPOT_Import!$A$1:$Z$2488,5,'Live Data'!$C$19)),"") -> 1000 | I5: =IFERROR(IF(INDEX(SPOT_Import!$A$1:$Z$2488,5,'Live Data'!$C$20)="","",INDEX(SPOT_Import!$A$1:$Z$2488,5,'Live Data'!$C$20)),"") -> Incomplete | J5: =IFERROR(IF(INDEX(SPOT_Import!$A$1:$Z$2488,5,'Live Data'!$C$21)="","",INDEX(SPOT_Import!$A$1:$Z$2488,5,'Live Data'!$C$21)),"") -> 2026-10-14T09:17:48.000Z | K5: =IFERROR(IF(INDEX(SPOT_Import!$A$1:$Z$2488,5,'Live Data'!$C$22)="","",INDEX(SPOT_Import!$A$1:$Z$2488,5,'Live Data'!$C$22)),"") -> 2026-10-14T09:17:48.000Z | L5: =IF(A5="","",IF(ISNUMBER(K5),TEXT(K5,"yyyy-mm"),LEFT(K5,7))) -> 2026-10 | M5: =IF(A5="","",UPPER(TRIM(SUBSTITUTE(C5," - ","-")))) -> EMBU | N5: =IF(A5="","",IFERROR(INDEX('Cluster Map'!$A$4:$A$38,MATCH(M5,'Cluster Map'!$B$4:$B$38,0)),"Unmapped")) -> Cluster 2 | O5: =IF(A5="",0,IF(COUNTIFS($A$2:A5,A5,$F$2:F5,F5,$L$2:L5,L5)=1,1,0)) -> 1 | P5: =IF(A5="",0,IF(AND(F5="C&T",COUNTIFS($A$2:A5,A5,$F$2:F5,"C&T")=1),1,0)) -> 0
A6: =IFERROR(IF(INDEX(SPOT_Import!$A$1:$Z$2488,6,'Live Data'!$C$12)="","",INDEX(SPOT_Import!$A$1:$Z$2488,6,'Live Data'!$C$12)),"") -> 12719 | B6: =IFERROR(IF(INDEX(SPOT_Import!$A$1:$Z$2488,6,'Live Data'!$C$13)="","",INDEX(SPOT_Import!$A$1:$Z$2488,6,'Live Data'!$C$13)),"") -> Runyenjes District Hospital | C6: =IFERROR(IF(INDEX(SPOT_Import!$A$1:$Z$2488,6,'Live Data'!$C$14)="","",INDEX(SPOT_Import!$A$1:$Z$2488,6,'Live Data'!$C$14)),"") -> EMBU | D6: =IFERROR(IF(INDEX(SPOT_Import!$A$1:$Z$2488,6,'Live Data'!$C$15)="","",INDEX(SPOT_Import!$A$1:$Z$2488,6,'Live Data'!$C$15)),"") -> Runyenjes | E6: =IFERROR(IF(INDEX(SPOT_Import!$A$1:$Z$2488,6,'Live Data'!$C$16)="","",INDEX(SPOT_Import!$A$1:$Z$2488,6,'Live Data'!$C$16)),"") -> USAID Jamii Tekelezi | F6: =IFERROR(IF(INDEX(SPOT_Import!$A$1:$Z$2488,6,'Live Data'!$C$17)="","",INDEX(SPOT_Import!$A$1:$Z$2488,6,'Live Data'!$C$17)),"") -> C&T | G6: =IFERROR(IF(INDEX(SPOT_Import!$A$1:$Z$2488,6,'Live Data'!$C$18)="","",INDEX(SPOT_Import!$A$1:$Z$2488,6,'Live Data'!$C$18)),"") -> 1938 | H6: =IFERROR(IF(INDEX(SPOT_Import!$A$1:$Z$2488,6,'Live Data'!$C$19)="","",INDEX(SPOT_Import!$A$1:$Z$2488,6,'Live Data'!$C$19)),"") -> 1938 | I6: =IFERROR(IF(INDEX(SPOT_Import!$A$1:$Z$2488,6,'Live Data'!$C$20)="","",INDEX(SPOT_Import!$A$1:$Z$2488,6,'Live Data'!$C$20)),"") -> Complete | J6: =IFERROR(IF(INDEX(SPOT_Import!$A$1:$Z$2488,6,'Live Data'!$C$21)="","",INDEX(SPOT_Import!$A$1:$Z$2488,6,'Live Data'!$C$21)),"") -> 2026-10-14T08:38:32.000Z | K6: =IFERROR(IF(INDEX(SPOT_Import!$A$1:$Z$2488,6,'Live Data'!$C$22)="","",INDEX(SPOT_Import!$A$1:$Z$2488,6,'Live Data'!$C$22)),"") -> 2026-10-14T08:38:32.000Z | L6: =IF(A6="","",IF(ISNUMBER(K6),TEXT(K6,"yyyy-mm"),LEFT(K6,7))) -> 2026-10 | M6: =IF(A6="","",UPPER(TRIM(SUBSTITUTE(C6," - ","-")))) -> EMBU | N6: =IF(A6="","",IFERROR(INDEX('Cluster Map'!$A$4:$A$38,MATCH(M6,'Cluster Map'!$B$4:$B$38,0)),"Unmapped")) -> Cluster 2 | O6: =IF(A6="",0,IF(COUNTIFS($A$2:A6,A6,$F$2:F6,F6,$L$2:L6,L6)=1,1,0)) -> 1 | P6: =IF(A6="",0,IF(AND(F6="C&T",COUNTIFS($A$2:A6,A6,$F$2:F6,"C&T")=1),1,0)) -> 1
